Workbook

Sheet 대시보드
A1: 2026-27 배움스키아카데미 운영 대시보드
A2: ="오늘 운영에 필요한 예약 · 상담 · 취소 · 현금흐름만 확인합니다. 기준일 "&TEXT(TODAY(),"yyyy-mm-dd") -> 오늘 운영에 필요한 예약 · 상담 · 취소 · 현금흐름만 확인합니다. 기준일 2026-10-06
A4: 시즌 예약 | C4: 오늘 강습 | E4: 상담 진행중 | G4: 취소 | I4: 예상순익
A5: =COUNTIFS(m_name,"<>",m_status,"결제완료") -> 1 | C5: =COUNTIFS(m_name,"<>",m_status,"결제완료",m_date,TODAY()) -> 0 | E5: =COUNTIFS(m_name,"<>",m_status,"상담중") -> 0 | G5: =COUNTIFS(m_name,"<>",m_status,"취소") -> 0 | I5: =월별결산!H14 -> 85000
A6: 결제완료 누적 | C6: =TEXT(TODAY(),"m/d")&" 결제완료 강습" -> 10/6 결제완료 강습 | E6: ="입금 전 · 예상 "&TEXT(SUMIFS(m_pay,m_name,"<>",m_status,"상담중"),"#,##0")&"원" -> 입금 전 · 예상 0원 | G6: ="취소 금액 "&TEXT(SUMIFS(m_pay,m_name,"<>",m_status,"취소"),"#,##0")&"원" -> 취소 금액 0원 | I6: ="순익률 "&TEXT(월별결산!H15,"0.0%") -> 순익률 65.4%
A8: 시즌 손익 (누적) | G8: 처리할 일
A9: 매출 | C9: =월별결산!H7 -> 130000 | E9: 결제완료 강습의 결제금액 | G9: 강사 일정 충돌 | J9: =IF(COUNTIF(m_conf,"충돌")=0,"없음",COUNTIF(m_conf,"충돌")&"건") -> 없음
A10: − 강사료 | C10: =월별결산!H8 -> 45000 | E10: 시급 × 강습시간 + 인원 추가 수당 | G10: 강사 미배정 (결제완료·상담중) | J10: =IF(SUMPRODUCT((m_active=1)*(m_teacher=""))=0,"없음",SUMPRODUCT((m_active=1)*(m_teacher=""))&"건") -> 없음
A11: − 장비 렌탈비 | C11: =월별결산!H9 -> 0 | E11: 장비대여 '대여' 건 × 렌탈비 | G11: 지난 상담 정리 (강습일 지남) | J11: =IF(SUMPRODUCT((m_name<>"")*(m_status="상담중")*(m_date<>"")*(m_date<TODAY()))=0,"없음",SUMPRODUCT((m_name<>"")*(m_status="상담중")*(m_date<>"")*(m_date<TODAY()))&"건") -> 없음
A12: − 네이버수수료 | C12: =월별결산!H11 -> 0 | E12: 스마트스토어 결제 × 수수료율 (자동) | G12: 예약상태 미입력 | J12: =IF(SUMPRODUCT((m_name<>"")*(m_status=""))=0,"없음",SUMPRODUCT((m_name<>"")*(m_status=""))&"건") -> 없음
A13: − 광고비·운영비 | C13: =월별결산!H12 -> 0 | E13: 운영비 탭 | G13: 날짜·시간 인식 안 됨 (빨간 칸) | J13: =IF(SUMPRODUCT((m_graw<>"")*(m_date=""))+SUMPRODUCT((m_hraw<>"")*(m_start=""))+SUMPRODUCT((m_iraw<>"")*(m_end=""))+SUMPRODUCT((m_praw<>"")*(m_paydate=""))=0,"없음",SUMPRODUCT((m_graw<>"")*(m_date=""))+SUMPRODUCT((m_hraw<>"")*(m_start=""))+SUMPRODUCT((m_iraw<>"")*(m_end=""))+SUMPRODUCT((m_praw<>"")*(m_paydate=""))&"건") -> 없음
A14: + 기타수입 | C14: =월별결산!H13 -> 0 | E14: 운영비 탭 | G14: 결제일 미입력 (결제완료) | J14: =IF(SUMPRODUCT((m_name<>"")*(m_status="결제완료")*(m_praw=""))=0,"없음",SUMPRODUCT((m_name<>"")*(m_status="결제완료")*(m_praw=""))&"건") -> 1건
A15: ＝ 예상순익 | C15: =월별결산!H14 -> 85000 | E15: 시즌 누적 | G15: 강사료 미정산 (지난 강습) | J15: =IF(SUMIFS(m_fee,m_date,"<"&TODAY(),m_settle,0)=0,"없음",TEXT(SUMIFS(m_fee,m_date,"<"&TODAY(),m_settle,0),"#,##0")&"원") -> 없음
A16: 월별 손익은 월별결산 탭 · 강사 지급은 강사정산 탭에서 확인 | G16: 리뷰 확인 (지난 결제완료 강습) | J16: =IF(SUMPRODUCT((m_name<>"")*(m_status="결제완료")*(m_date<>"")*(m_date<TODAY())*(m_review=""))=0,"없음",SUMPRODUCT((m_name<>"")*(m_status="결제완료")*(m_date<>"")*(m_date<TODAY())*(m_review=""))&"건") -> 없음
G17: 퇴사 강사에게 남은 강습 | J17: =IF(SUMPRODUCT((m_retired=1)*(m_date<>"")*(m_date>=TODAY()))=0,"없음",SUMPRODUCT((m_retired=1)*(m_date<>"")*(m_date>=TODAY()))&"건") -> 없음
A19: 예약경로별 성과 | G19: 월별 요약 (강습일 기준)
A20: 예약경로 | C20: 결제완료 | D20: 상담중 | E20: 매출 | G20: 월 | H20: 예약 | I20: 매출 | J20: 예상순익
A21: =IF(설정!$C$4="","",설정!$C$4) -> 스마트스토어 | C21: =IF($A21="","",COUNTIFS(m_route,$A21,m_status,"결제완료",m_name,"<>")) -> 0 | D21: =IF($A21="","",COUNTIFS(m_route,$A21,m_status,"상담중",m_name,"<>")) -> 0 | E21: =IF($A21="","",SUMIFS(m_rev,m_route,$A21)) -> 0 | G21: =월별결산!B3 -> 46327 | H21: =월별결산!B5 -> 0 | I21: =월별결산!B7 -> 0 | J21: =월별결산!B14 -> 0
A22: =IF(설정!$C$5="","",설정!$C$5) -> 홈페이지 | C22: =IF($A22="","",COUNTIFS(m_route,$A22,m_status,"결제완료",m_name,"<>")) -> 0 | D22: =IF($A22="","",COUNTIFS(m_route,$A22,m_status,"상담중",m_name,"<>")) -> 0 | E22: =IF($A22="","",SUMIFS(m_rev,m_route,$A22)) -> 0 | G22: =월별결산!C3 -> 46357 | H22: =월별결산!C5 -> 0 | I22: =월별결산!C7 -> 0 | J22: =월별결산!C14 -> 0
A23: =IF(설정!$C$6="","",설정!$C$6) -> 오픈채팅 | C23: =IF($A23="","",COUNTIFS(m_route,$A23,m_status,"결제완료",m_name,"<>")) -> 0 | D23: =IF($A23="","",COUNTIFS(m_route,$A23,m_status,"상담중",m_name,"<>")) -> 0 | E23: =IF($A23="","",SUMIFS(m_rev,m_route,$A23)) -> 0 | G23: =월별결산!D3 -> 46388 | H23: =월별결산!D5 -> 1 | I23: =월별결산!D7 -> 130000 | J23: =월별결산!D14 -> 85000
A24: =IF(설정!$C$7="","",설정!$C$7) -> 당근 | C24: =IF($A24="","",COUNTIFS(m_route,$A24,m_status,"결제완료",m_name,"<>")) -> 0 | D24: =IF($A24="","",COUNTIFS(m_route,$A24,m_status,"상담중",m_name,"<>")) -> 0 | E24: =IF($A24="","",SUMIFS(m_rev,m_route,$A24)) -> 0 | G24: =월별결산!E3 -> 46419 | H24: =월별결산!E5 -> 0 | I24: =월별결산!E7 -> 0 | J24: =월별결산!E14 -> 0
A25: =IF(설정!$C$8="","",설정!$C$8) -> 블로그 | C25: =IF($A25="","",COUNTIFS(m_route,$A25,m_status,"결제완료",m_name,"<>")) -> 0 | D25: =IF($A25="","",COUNTIFS(m_route,$A25,m_status,"상담중",m_name,"<>")) -> 0 | E25: =IF($A25="","",SUMIFS(m_rev,m_route,$A25)) -> 0 | G25: =월별결산!F3 -> 46447 | H25: =월별결산!F5 -> 0 | I25: =월별결산!F7 -> 0 | J25: =월별결산!F14 -> 0
A26: =IF(설정!$C$9="","",설정!$C$9) -> 인스타 | C26: =IF($A26="","",COUNTIFS(m_route,$A26,m_status,"결제완료",m_name,"<>")) -> 0 | D26: =IF($A26="","",COUNTIFS(m_route,$A26,m_status,"상담중",m_name,"<>")) -> 0 | E26: =IF($A26="","",SUMIFS(m_rev,m_route,$A26)) -> 0 | G26: 기간 외 | H26: =월별결산!G5 -> 0 | I26: =월별결산!G7 -> 0 | J26: =월별결산!G14 -> 0
A27: =IF(설정!$C$10="","",설정!$C$10) -> 맘카페 | C27: =IF($A27="","",COUNTIFS(m_route,$A27,m_status,"결제완료",m_name,"<>")) -> 0 | D27: =IF($A27="","",COUNTIFS(m_route,$A27,m_status,"상담중",m_name,"<>")) -> 0 | E27: =IF($A27="","",SUMIFS(m_rev,m_route,$A27)) -> 0 | G27: 합계 | H27: =월별결산!H5 -> 1 | I27: =월별결산!H7 -> 130000 | J27: =월별결산!H14 -> 85000
A28: =IF(설정!$C$11="","",설정!$C$11) -> 소개 | C28: =IF($A28="","",COUNTIFS(m_route,$A28,m_status,"결제완료",m_name,"<>")) -> 0 | D28: =IF($A28="","",COUNTIFS(m_route,$A28,m_status,"상담중",m_name,"<>")) -> 0 | E28: =IF($A28="","",SUMIFS(m_rev,m_route,$A28)) -> 0
A29: =IF(설정!$C$12="","",설정!$C$12) -> 재방문 | C29: =IF($A29="","",COUNTIFS(m_route,$A29,m_status,"결제완료",m_name,"<>")) -> 0 | D29: =IF($A29="","",COUNTIFS(m_route,$A29,m_status,"상담중",m_name,"<>")) -> 0 | E29: =IF($A29="","",SUMIFS(m_rev,m_route,$A29)) -> 0
A30: =IF(설정!$C$13="","",설정!$C$13) -> 기타 | C30: =IF($A30="","",COUNTIFS(m_route,$A30,m_status,"결제완료",m_name,"<>")) -> 0 | D30: =IF($A30="","",COUNTIFS(m_route,$A30,m_status,"상담중",m_name,"<>")) -> 0 | E30: =IF($A30="","",SUMIFS(m_rev,m_route,$A30)) -> 0
A31: =IF(설정!$C$14="","",설정!$C$14) | C31: =IF($A31="","",COUNTIFS(m_route,$A31,m_status,"결제완료",m_name,"<>")) | D31: =IF($A31="","",COUNTIFS(m_route,$A31,m_status,"상담중",m_name,"<>")) | E31: =IF($A31="","",SUMIFS(m_rev,m_route,$A31))
A32: =IF(설정!$C$15="","",설정!$C$15) | C32: =IF($A32="","",COUNTIFS(m_route,$A32,m_status,"결제완료",m_name,"<>")) | D32: =IF($A32="","",COUNTIFS(m_route,$A32,m_status,"상담중",m_name,"<>")) | E32: =IF($A32="","",SUMIFS(m_rev,m_route,$A32))
A33: 미입력·기타 | C33: =COUNTIFS(m_name,"<>",m_status,"결제완료")-SUM(C21:C32) -> 1 | D33: =COUNTIFS(m_name,"<>",m_status,"상담중")-SUM(D21:D32) -> 0 | E33: =SUM(m_rev)-SUM(E21:E32) -> 130000
A35: ※ 고객·예약 입력 → 관리자_MASTER · 일정 → 강습표 탭 · 월별 손익 → 월별결산 · 강사 지급 → 강사정산 · 비용 → 운영비

Sheet 관리자_MASTER
A1: 2026-27 배움스키아카데미 관리자 MASTER · 고객·예약 원장
A2: 날짜는 2026-12-25 또는 20261225, 시간은 10:00 · 1000 · 10 중 편한 방식 (빨간 칸 = 인식 못 한 값). 예약자 칸을 채워야 집계·강습표에 반영됩니다. 흰 칸만 입력하고 연한 파랑 칸(자동)은 지우지 마세요. 빈 행에 이어서 입력(행 삽입 X).
A3: 예약상태: 상담중(입금 전) → 결제완료(입금 확인) · 취소(입금 전 취소, 환불한 건 모두). 실제 고객 건은 행을 지우지 말고 상태만 바꾸세요. 강사료·지급·비용은 강사정산·운영비 탭에서 관리합니다.
A4: No (자동) | B4: 예약상태 | C4: 접수일 | D4: 예약자 | E4: 연락처 | F4: 강습생 (쉼표로 구분) | G4: 강습일 | H4: 시작 | I4: 종료 | J4: 강습시간(h) (자동) | K4: 인원 (자동) | L4: 유형 (자동) | M4: 담당강사 | N4: 결제금액 | O4: 결제방식 | P4: 결제일 | Q4: 예약경로 | R4: 특이사항 | S4: 일정충돌 (자동) | T4: 장비대여 | U4: 강습일(계산) | V4: 시작(분) | W4: 종료(분) | X4: 결제일(계산) | Y4: 시급 | Z4: 강사료 | AA4: 매출 | AB4: 강습표 표시 | AC4: 활성 | AD4: 정산번호 | AE4: 리뷰 작성 | AF4: 장비비 | AG4: 강습표 특이사항 | AH4: 네이버수수료 | AI4: 행번호 | AJ4: 퇴사강사
A5: =IF($D5="","",COUNTA($D$5:$D5)) -> 1 | B5: 결제완료 | D5: 김건진 | E5: 010-7356-5258 | F5: 김태준(10), 김명국(12) | G5: 46393 | H5: 0.41666667 | I5: 0.5 | J5: =IF(OR($V5="",$W5=""),"",ROUND(($W5-$V5)/60,2)) -> 2 | K5: =IF($F5="","",LEN($F5)-LEN(SUBSTITUTE($F5,",",""))+1) -> 2 | L5: =IF($K5="","","1:"&$K5) -> 1:2 | M5: 박세근 | N5: 130000 | O5: 계좌 | S5: =IF(OR($AC5=0,$U5="",$M5="",$V5="",$W5=""),"",IF(COUNTIFS(m_teacher,$M5,m_date,$U5,m_active,1,m_start,"<"&$W5,m_end,">"&$V5)>1,"충돌","")) | U5: =IF($G5="","",IFERROR(IF(ISNUMBER($G5),IF($G5>19000000,DATE(INT($G5/10000),MOD(INT($G5/100),100),MOD($G5,100)),INT($G5)),IF(LEN(SUBSTITUTE(SUBSTITUTE(SUBSTITUTE(TRIM($G5),"-",""),".",""),"/",""))=8,DATE(VALUE(LEFT(SUBSTITUTE(SUBSTITUTE(SUBSTITUTE(TRIM($G5),"-",""),".",""),"/",""),4)),VALUE(MID(SUBSTITUTE(SUBSTITUTE(SUBSTITUTE(TRIM($G5),"-",""),".",""),"/",""),5,2)),VALUE(RIGHT(SUBSTITUTE(SUBSTITUTE(SUBSTITUTE(TRIM($G5),"-",""),".",""),"/",""),2))),DATEVALUE($G5))),"")) -> 46393 | V5: =IF($H5="","",IFERROR(IF(IF(ISNUMBER($H5),$H5,IFERROR(TIMEVALUE($H5),VALUE($H5)))>=100,INT(IF(ISNUMBER($H5),$H5,IFERROR(TIMEVALUE($H5),VALUE($H5)))/100)*60+MOD(IF(ISNUMBER($H5),$H5,IFERROR(TIMEVALUE($H5),VALUE($H5))),100),IF(IF(ISNUMBER($H5),$H5,IFERROR(TIMEVALUE($H5),VALUE($H5)))>=1,ROUND(IF(ISNUMBER($H5),$H5,IFERROR(TIMEVALUE($H5),VALUE($H5)))*60,0),ROUND(MOD(IF(ISNUMBER($H5),$H5,IFERROR(TIMEVALUE($H5),VALUE($H5))),1)*1440,0))),"")) -> 600 | W5: =IF($I5="","",IFERROR(IF(IF(ISNUMBER($I5),$I5,IFERROR(TIMEVALUE($I5),VALUE($I5)))>=100,INT(IF(ISNUMBER($I5),$I5,IFERROR(TIMEVALUE($I5),VALUE($I5)))/100)*60+MOD(IF(ISNUMBER($I5),$I5,IFERROR(TIMEVALUE($I5),VALUE($I5))),100),IF(IF(ISNUMBER($I5),$I5,IFERROR(TIMEVALUE($I5),VALUE($I5)))>=1,ROUND(IF(ISNUMBER($I5),$I5,IFERROR(TIMEVALUE($I5),VALUE($I5)))*60,0),ROUND(MOD(IF(ISNUMBER($I5),$I5,IFERROR(TIMEVALUE($I5),VALUE($I5))),1)*1440,0))),"")) -> 720 | X5: =IF($P5="","",IFERROR(IF(ISNUMBER($P5),IF($P5>19000000,DATE(INT($P5/10000),MOD(INT($P5/100),100),MOD($P5,100)),INT($P5)),IF(LEN(SUBSTITUTE(SUBSTITUTE(SUBSTITUTE(TRIM($P5),"-",""),".",""),"/",""))=8,DATE(VALUE(LEFT(SUBSTITUTE(SUBSTITUTE(SUBSTITUTE(TRIM($P5),"-",""),".",""),"/",""),4)),VALUE(MID(SUBSTITUTE(SUBSTITUTE(SUBSTITUTE(TRIM($P5),"-",""),".",""),"/",""),5,2)),VALUE(RIGHT(SUBSTITUTE(SUBSTITUTE(SUBSTITUTE(TRIM($P5),"-",""),".",""),"/",""),2))),DATEVALUE($P5))),"")) | Y5: =IF($M5="","",IFERROR(INDEX(강사DB!$D$4:$D$53,MATCH($M5,강사DB!$A$4:$A$53,0)),"")) -> 20000 | Z5: =IF($B5<>"결제완료","",IF(OR($Y5="",$J5=""),"",$Y5*$J5+MAX(0,N($K5)-1)*설정!$J$7)) -> 45000 | AA5: =IF(AND($D5<>"",$B5="결제완료"),N($N5),"") -> 130000 | AB5: =IF($D5="","",IF($F5<>"",$F5,$D5)&IF($B5="상담중"," (상담)","")) -> 김태준(10), 김명국(12) | AC5: =IF(AND($D5<>"",OR($B5="결제완료",$B5="상담중")),1,0) -> 1 | AD5: =IF(OR($Z5="",$U5=""),0,IFERROR(IF(COUNTIFS(INDEX(g_grid,0,2*MATCH($M5,강사DB!$A$4:$A$15,0)),"<>",g_s,"<="&$U5,g_e,">="&$U5)>0,1,0),0)) -> 0 | AF5: =IF(AND($D5<>"",$B5="결제완료",$T5="대여"),설정!$J$5,"") | AG5: =IF($D5="","",IF(AND($E5="",$R5=""),$AB5,"☎ "&IF($E5="","-",$E5)&IF($R5<>""," ※ "&$R5,"")&IF($B5="상담중"," (상담)",""))) -> ☎ 010-7356-5258 | AH5: =IF(AND($D5<>"",$B5="결제완료",$O5="스마트스토어"),ROUND(N($N5)*설정!$J$6,0),"") | AI5: =IF($D5="","",ROW()) -> 5 | AJ5: =IF(OR($AC5<>1,$M5=""),0,IF(ISNUMBER(SEARCH("퇴사",IFERROR(INDEX(강사DB!$G$4:$G$53,MATCH($M5,강사DB!$A$4:$A$53,0)),""))),1,0)) -> 0
A6: =IF($D6="","",COUNTA($D$5:$D6)) | J6: =IF(OR($V6="",$W6=""),"",ROUND(($W6-$V6)/60,2)) | K6: =IF($F6="","",LEN($F6)-LEN(SUBSTITUTE($F6,",",""))+1) | L6: =IF($K6="","","1:"&$K6) | S6: =IF(OR($AC6=0,$U6="",$M6="",$V6="",$W6=""),"",IF(COUNTIFS(m_teacher,$M6,m_date,$U6,m_active,1,m_start,"<"&$W6,m_end,">"&$V6)>1,"충돌","")) | U6: =IF($G6="","",IFERROR(IF(ISNUMBER($G6),IF($G6>19000000,DATE(INT($G6/10000),MOD(INT($G6/100),100),MOD($G6,100)),INT($G6)),IF(LEN(SUBSTITUTE(SUBSTITUTE(SUBSTITUTE(TRIM($G6),"-",""),".",""),"/",""))=8,DATE(VALUE(LEFT(SUBSTITUTE(SUBSTITUTE(SUBSTITUTE(TRIM($G6),"-",""),".",""),"/",""),4)),VALUE(MID(SUBSTITUTE(SUBSTITUTE(SUBSTITUTE(TRIM($G6),"-",""),".",""),"/",""),5,2)),VALUE(RIGHT(SUBSTITUTE(SUBSTITUTE(SUBSTITUTE(TRIM($G6),"-",""),".",""),"/",""),2))),DATEVALUE($G6))),"")) | V6: =IF($H6="","",IFERROR(IF(IF(ISNUMBER($H6),$H6,IFERROR(TIMEVALUE($H6),VALUE($H6)))>=100,INT(IF(ISNUMBER($H6),$H6,IFERROR(TIMEVALUE($H6),VALUE($H6)))/100)*60+MOD(IF(ISNUMBER($H6),$H6,IFERROR(TIMEVALUE($H6),VALUE($H6))),100),IF(IF(ISNUMBER($H6),$H6,IFERROR(TIMEVALUE($H6),VALUE($H6)))>=1,ROUND(IF(ISNUMBER($H6),$H6,IFERROR(TIMEVALUE($H6),VALUE($H6)))*60,0),ROUND(MOD(IF(ISNUMBER($H6),$H6,IFERROR(TIMEVALUE($H6),VALUE($H6))),1)*1440,0))),"")) | W6: =IF($I6="","",IFERROR(IF(IF(ISNUMBER($I6),$I6,IFERROR(TIMEVALUE($I6),VALUE($I6)))>=100,INT(IF(ISNUMBER($I6),$I6,IFERROR(TIMEVALUE($I6),VALUE($I6)))/100)*60+MOD(IF(ISNUMBER($I6),$I6,IFERROR(TIMEVALUE($I6),VALUE($I6))),100),IF(IF(ISNUMBER($I6),$I6,IFERROR(TIMEVALUE($I6),VALUE($I6)))>=1,ROUND(IF(ISNUMBER($I6),$I6,IFERROR(TIMEVALUE($I6),VALUE($I6)))*60,0),ROUND(MOD(IF(ISNUMBER($I6),$I6,IFERROR(TIMEVALUE($I6),VALUE($I6))),1)*1440,0))),"")) | X6: =IF($P6="","",IFERROR(IF(ISNUMBER($P6),IF($P6>19000000,DATE(INT($P6/10000),MOD(INT($P6/100),100),MOD($P6,100)),INT($P6)),IF(LEN(SUBSTITUTE(SUBSTITUTE(SUBSTITUTE(TRIM($P6),"-",""),".",""),"/",""))=8,DATE(VALUE(LEFT(SUBSTITUTE(SUBSTITUTE(SUBSTITUTE(TRIM($P6),"-",""),".",""),"/",""),4)),VALUE(MID(SUBSTITUTE(SUBSTITUTE(SUBSTITUTE(TRIM($P6),"-",""),".",""),"/",""),5,2)),VALUE(RIGHT(SUBSTITUTE(SUBSTITUTE(SUBSTITUTE(TRIM($P6),"-",""),".",""),"/",""),2))),DATEVALUE($P6))),"")) | Y6: =IF($M6="","",IFERROR(INDEX(강사DB!$D$4:$D$53,MATCH($M6,강사DB!$A$4:$A$53,0)),"")) | Z6: =IF($B6<>"결제완료","",IF(OR($Y6="",$J6=""),"",$Y6*$J6+MAX(0,N($K6)-1)*설정!$J$7)) | AA6: =IF(AND($D6<>"",$B6="결제완료"),N($N6),"") | AB6: =IF($D6="","",IF($F6<>"",$F6,$D6)&IF($B6="상담중"," (상담)","")) | AC6: =IF(AND($D6<>"",OR($B6="결제완료",$B6="상담중")),1,0) -> 0 | AD6: =IF(OR($Z6="",$U6=""),0,IFERROR(IF(COUNTIFS(INDEX(g_grid,0,2*MATCH($M6,강사DB!$A$4:$A$15,0)),"<>",g_s,"<="&$U6,g_e,">="&$U6)>0,1,0),0)) -> 0 | AF6: =IF(AND($D6<>"",$B6="결제완료",$T6="대여"),설정!$J$5,"") | AG6: =IF($D6="","",IF(AND($E6="",$R6=""),$AB6,"☎ "&IF($E6="","-",$E6)&IF($R6<>""," ※ "&$R6,"")&IF($B6="상담중"," (상담)",""))) | AH6: =IF(AND($D6<>"",$B6="결제완료",$O6="스마트스토어"),ROUND(N($N6)*설정!$J$6,0),"") | AI6: =IF($D6="","",ROW()) | AJ6: =IF(OR($AC6<>1,$M6=""),0,IF(ISNUMBER(SEARCH("퇴사",IFERROR(INDEX(강사DB!$G$4:$G$53,MATCH($M6,강사DB!$A$4:$A$53,0)),""))),1,0)) -> 0
A7: =IF($D7="","",COUNTA($D$5:$D7)) | J7: =IF(OR($V7="",$W7=""),"",ROUND(($W7-$V7)/60,2)) | K7: =IF($F7="","",LEN($F7)-LEN(SUBSTITUTE($F7,",",""))+1) | L7: =IF($K7="","","1:"&$K7) | S7: =IF(OR($AC7=0,$U7="",$M7="",$V7="",$W7=""),"",IF(COUNTIFS(m_teacher,$M7,m_date,$U7,m_active,1,m_start,"<"&$W7,m_end,">"&$V7)>1,"충돌","")) | U7: =IF($G7="","",IFERROR(IF(ISNUMBER($G7),IF($G7>19000000,DATE(INT($G7/10000),MOD(INT($G7/100),100),MOD($G7,100)),INT($G7)),IF(LEN(SUBSTITUTE(SUBSTITUTE(SUBSTITUTE(TRIM($G7),"-",""),".",""),"/",""))=8,DATE(VALUE(LEFT(SUBSTITUTE(SUBSTITUTE(SUBSTITUTE(TRIM($G7),"-",""),".",""),"/",""),4)),VALUE(MID(SUBSTITUTE(SUBSTITUTE(SUBSTITUTE(TRIM($G7),"-",""),".",""),"/",""),5,2)),VALUE(RIGHT(SUBSTITUTE(SUBSTITUTE(SUBSTITUTE(TRIM($G7),"-",""),".",""),"/",""),2))),DATEVALUE($G7))),"")) | V7: =IF($H7="","",IFERROR(IF(IF(ISNUMBER($H7),$H7,IFERROR(TIMEVALUE($H7),VALUE($H7)))>=100,INT(IF(ISNUMBER($H7),$H7,IFERROR(TIMEVALUE($H7),VALUE($H7)))/100)*60+MOD(IF(ISNUMBER($H7),$H7,IFERROR(TIMEVALUE($H7),VALUE($H7))),100),IF(IF(ISNUMBER($H7),$H7,IFERROR(TIMEVALUE($H7),VALUE($H7)))>=1,ROUND(IF(ISNUMBER($H7),$H7,IFERROR(TIMEVALUE($H7),VALUE($H7)))*60,0),ROUND(MOD(IF(ISNUMBER($H7),$H7,IFERROR(TIMEVALUE($H7),VALUE($H7))),1)*1440,0))),"")) | W7: =IF($I7="","",IFERROR(IF(IF(ISNUMBER($I7),$I7,IFERROR(TIMEVALUE($I7),VALUE($I7)))>=100,INT(IF(ISNUMBER($I7),$I7,IFERROR(TIMEVALUE($I7),VALUE($I7)))/100)*60+MOD(IF(ISNUMBER($I7),$I7,IFERROR(TIMEVALUE($I7),VALUE($I7))),100),IF(IF(ISNUMBER($I7),$I7,IFERROR(TIMEVALUE($I7),VALUE($I7)))>=1,ROUND(IF(ISNUMBER($I7),$I7,IFERROR(TIMEVALUE($I7),VALUE($I7)))*60,0),ROUND(MOD(IF(ISNUMBER($I7),$I7,IFERROR(TIMEVALUE($I7),VALUE($I7))),1)*1440,0))),"")) | X7: =IF($P7="","",IFERROR(IF(ISNUMBER($P7),IF($P7>19000000,DATE(INT($P7/10000),MOD(INT($P7/100),100),MOD($P7,100)),INT($P7)),IF(LEN(SUBSTITUTE(SUBSTITUTE(SUBSTITUTE(TRIM($P7),"-",""),".",""),"/",""))=8,DATE(VALUE(LEFT(SUBSTITUTE(SUBSTITUTE(SUBSTITUTE(TRIM($P7),"-",""),".",""),"/",""),4)),VALUE(MID(SUBSTITUTE(SUBSTITUTE(SUBSTITUTE(TRIM($P7),"-",""),".",""),"/",""),5,2)),VALUE(RIGHT(SUBSTITUTE(SUBSTITUTE(SUBSTITUTE(TRIM($P7),"-",""),".",""),"/",""),2))),DATEVALUE($P7))),"")) | Y7: =IF($M7="","",IFERROR(INDEX(강사DB!$D$4:$D$53,MATCH($M7,강사DB!$A$4:$A$53,0)),"")) | Z7: =IF($B7<>"결제완료","",IF(OR($Y7="",$J7=""),"",$Y7*$J7+MAX(0,N($K7)-1)*설정!$J$7)) | AA7: =IF(AND($D7<>"",$B7="결제완료"),N($N7),"") | AB7: =IF($D7="","",IF($F7<>"",$F7,$D7)&IF($B7="상담중"," (상담)","")) | AC7: =IF(AND($D7<>"",OR($B7="결제완료",$B7="상담중")),1,0) -> 0 | AD7: =IF(OR($Z7="",$U7=""),0,IFERROR(IF(COUNTIFS(INDEX(g_grid,0,2*MATCH($M7,강사DB!$A$4:$A$15,0)),"<>",g_s,"<="&$U7,g_e,">="&$U7)>0,1,0),0)) -> 0 | AF7: =IF(AND($D7<>"",$B7="결제완료",$T7="대여"),설정!$J$5,"") | AG7: =IF($D7="","",IF(AND($E7="",$R7=""),$AB7,"☎ "&IF($E7="","-",$E7)&IF($R7<>""," ※ "&$R7,"")&IF($B7="상담중"," (상담)",""))) | AH7: =IF(AND($D7<>"",$B7="결제완료",$O7="스마트스토어"),ROUND(N($N7)*설정!$J$6,0),"") | AI7: =IF($D7="","",ROW()) | AJ7: =IF(OR($AC7<>1,$M7=""),0,IF(ISNUMBER(SEARCH("퇴사",IFERROR(INDEX(강사DB!$G$4:$G$53,MATCH($M7,강사DB!$A$4:$A$53,0)),""))),1,0)) -> 0
A8: =IF($D8="","",COUNTA($D$5:$D8)) | J8: =IF(OR($V8="",$W8=""),"",ROUND(($W8-$V8)/60,2)) | K8: =IF($F8="","",LEN($F8)-LEN(SUBSTITUTE($F8,",",""))+1) | L8: =IF($K8="","","1:"&$K8) | S8: =IF(OR($AC8=0,$U8="",$M8="",$V8="",$W8=""),"",IF(COUNTIFS(m_teacher,$M8,m_date,$U8,m_active,1,m_start,"<"&$W8,m_end,">"&$V8)>1,"충돌","")) | U8: =IF($G8="","",IFERROR(IF(ISNUMBER($G8),IF($G8>19000000,DATE(INT($G8/10000),MOD(INT($G8/100),100),MOD($G8,100)),INT($G8)),IF(LEN(SUBSTITUTE(SUBSTITUTE(SUBSTITUTE(TRIM($G8),"-",""),".",""),"/",""))=8,DATE(VALUE(LEFT(SUBSTITUTE(SUBSTITUTE(SUBSTITUTE(TRIM($G8),"-",""),".",""),"/",""),4)),VALUE(MID(SUBSTITUTE(SUBSTITUTE(SUBSTITUTE(TRIM($G8),"-",""),".",""),"/",""),5,2)),VALUE(RIGHT(SUBSTITUTE(SUBSTITUTE(SUBSTITUTE(TRIM($G8),"-",""),".",""),"/",""),2))),DATEVALUE($G8))),"")) | V8: =IF($H8="","",IFERROR(IF(IF(ISNUMBER($H8),$H8,IFERROR(TIMEVALUE($H8),VALUE($H8)))>=100,INT(IF(ISNUMBER($H8),$H8,IFERROR(TIMEVALUE($H8),VALUE($H8)))/100)*60+MOD(IF(ISNUMBER($H8),$H8,IFERROR(TIMEVALUE($H8),VALUE($H8))),100),IF(IF(ISNUMBER($H8),$H8,IFERROR(TIMEVALUE($H8),VALUE($H8)))>=1,ROUND(IF(ISNUMBER($H8),$H8,IFERROR(TIMEVALUE($H8),VALUE($H8)))*60,0),ROUND(MOD(IF(ISNUMBER($H8),$H8,IFERROR(TIMEVALUE($H8),VALUE($H8))),1)*1440,0))),"")) | W8: =IF($I8="","",IFERROR(IF(IF(ISNUMBER($I8),$I8,IFERROR(TIMEVALUE($I8),VALUE($I8)))>=100,INT(IF(ISNUMBER($I8),$I8,IFERROR(TIMEVALUE($I8),VALUE($I8)))/100)*60+MOD(IF(ISNUMBER($I8),$I8,IFERROR(TIMEVALUE($I8),VALUE($I8))),100),IF(IF(ISNUMBER($I8),$I8,IFERROR(TIMEVALUE($I8),VALUE($I8)))>=1,ROUND(IF(ISNUMBER($I8),$I8,IFERROR(TIMEVALUE($I8),VALUE($I8)))*60,0),ROUND(MOD(IF(ISNUMBER($I8),$I8,IFERROR(TIMEVALUE($I8),VALUE($I8))),1)*1440,0))),"")) | X8: =IF($P8="","",IFERROR(IF(ISNUMBER($P8),IF($P8>19000000,DATE(INT($P8/10000),MOD(INT($P8/100),100),MOD($P8,100)),INT($P8)),IF(LEN(SUBSTITUTE(SUBSTITUTE(SUBSTITUTE(TRIM($P8),"-",""),".",""),"/",""))=8,DATE(VALUE(LEFT(SUBSTITUTE(SUBSTITUTE(SUBSTITUTE(TRIM($P8),"-",""),".",""),"/",""),4)),VALUE(MID(SUBSTITUTE(SUBSTITUTE(SUBSTITUTE(TRIM($P8),"-",""),".",""),"/",""),5,2)),VALUE(RIGHT(SUBSTITUTE(SUBSTITUTE(SUBSTITUTE(TRIM($P8),"-",""),".",""),"/",""),2))),DATEVALUE($P8))),"")) | Y8: =IF($M8="","",IFERROR(INDEX(강사DB!$D$4:$D$53,MATCH($M8,강사DB!$A$4:$A$53,0)),"")) | Z8: =IF($B8<>"결제완료","",IF(OR($Y8="",$J8=""),"",$Y8*$J8+MAX(0,N($K8)-1)*설정!$J$7)) | AA8: =IF(AND($D8<>"",$B8="결제완료"),N($N8),"") | AB8: =IF($D8="","",IF($F8<>"",$F8,$D8)&IF($B8="상담중"," (상담)","")) | AC8: =IF(AND($D8<>"",OR($B8="결제완료",$B8="상담중")),1,0) -> 0 | AD8: =IF(OR($Z8="",$U8=""),0,IFERROR(IF(COUNTIFS(INDEX(g_grid,0,2*MATCH($M8,강사DB!$A$4:$A$15,0)),"<>",g_s,"<="&$U8,g_e,">="&$U8)>0,1,0),0)) -> 0 | AF8: =IF(AND($D8<>"",$B8="결제완료",$T8="대여"),설정!$J$5,"") | AG8: =IF($D8="","",IF(AND($E8="",$R8=""),$AB8,"☎ "&IF($E8="","-",$E8)&IF($R8<>""," ※ "&$R8,"")&IF($B8="상담중"," (상담)",""))) | AH8: =IF(AND($D8<>"",$B8="결제완료",$O8="스마트스토어"),ROUND(N($N8)*설정!$J$6,0),"") | AI8: =IF($D8="","",ROW()) | AJ8: =IF(OR($AC8<>1,$M8=""),0,IF(ISNUMBER(SEARCH("퇴사",IFERROR(INDEX(강사DB!$G$4:$G$53,MATCH($M8,강사DB!$A$4:$A$53,0)),""))),1,0)) -> 0
A9: =IF($D9="","",COUNTA($D$5:$D9)) | J9: =IF(OR($V9="",$W9=""),"",ROUND(($W9-$V9)/60,2)) | K9: =IF($F9="","",LEN($F9)-LEN(SUBSTITUTE($F9,",",""))+1) | L9: =IF($K9="","","1:"&$K9) | S9: =IF(OR($AC9=0,$U9="",$M9="",$V9="",$W9=""),"",IF(COUNTIFS(m_teacher,$M9,m_date,$U9,m_active,1,m_start,"<"&$W9,m_end,">"&$V9)>1,"충돌","")) | U9: =IF($G9="","",IFERROR(IF(ISNUMBER($G9),IF($G9>19000000,DATE(INT($G9/10000),MOD(INT($G9/100),100),MOD($G9,100)),INT($G9)),IF(LEN(SUBSTITUTE(SUBSTITUTE(SUBSTITUTE(TRIM($G9),"-",""),".",""),"/",""))=8,DATE(VALUE(LEFT(SUBSTITUTE(SUBSTITUTE(SUBSTITUTE(TRIM($G9),"-",""),".",""),"/",""),4)),VALUE(MID(SUBSTITUTE(SUBSTITUTE(SUBSTITUTE(TRIM($G9),"-",""),".",""),"/",""),5,2)),VALUE(RIGHT(SUBSTITUTE(SUBSTITUTE(SUBSTITUTE(TRIM($G9),"-",""),".",""),"/",""),2))),DATEVALUE($G9))),"")) | V9: =IF($H9="","",IFERROR(IF(IF(ISNUMBER($H9),$H9,IFERROR(TIMEVALUE($H9),VALUE($H9)))>=100,INT(IF(ISNUMBER($H9),$H9,IFERROR(TIMEVALUE($H9),VALUE($H9)))/100)*60+MOD(IF(ISNUMBER($H9),$H9,IFERROR(TIMEVALUE($H9),VALUE($H9))),100),IF(IF(ISNUMBER($H9),$H9,IFERROR(TIMEVALUE($H9),VALUE($H9)))>=1,ROUND(IF(ISNUMBER($H9),$H9,IFERROR(TIMEVALUE($H9),VALUE($H9)))*60,0),ROUND(MOD(IF(ISNUMBER($H9),$H9,IFERROR(TIMEVALUE($H9),VALUE($H9))),1)*1440,0))),"")) | W9: =IF($I9="","",IFERROR(IF(IF(ISNUMBER($I9),$I9,IFERROR(TIMEVALUE($I9),VALUE($I9)))>=100,INT(IF(ISNUMBER($I9),$I9,IFERROR(TIMEVALUE($I9),VALUE($I9)))/100)*60+MOD(IF(ISNUMBER($I9),$I9,IFERROR(TIMEVALUE($I9),VALUE($I9))),100),IF(IF(ISNUMBER($I9),$I9,IFERROR(TIMEVALUE($I9),VALUE($I9)))>=1,ROUND(IF(ISNUMBER($I9),$I9,IFERROR(TIMEVALUE($I9),VALUE($I9)))*60,0),ROUND(MOD(IF(ISNUMBER($I9),$I9,IFERROR(TIMEVALUE($I9),VALUE($I9))),1)*1440,0))),"")) | X9: =IF($P9="","",IFERROR(IF(ISNUMBER($P9),IF($P9>19000000,DATE(INT($P9/10000),MOD(INT($P9/100),100),MOD($P9,100)),INT($P9)),IF(LEN(SUBSTITUTE(SUBSTITUTE(SUBSTITUTE(TRIM($P9),"-",""),".",""),"/",""))=8,DATE(VALUE(LEFT(SUBSTITUTE(SUBSTITUTE(SUBSTITUTE(TRIM($P9),"-",""),".",""),"/",""),4)),VALUE(MID(SUBSTITUTE(SUBSTITUTE(SUBSTITUTE(TRIM($P9),"-",""),".",""),"/",""),5,2)),VALUE(RIGHT(SUBSTITUTE(SUBSTITUTE(SUBSTITUTE(TRIM($P9),"-",""),".",""),"/",""),2))),DATEVALUE($P9))),"")) | Y9: =IF($M9="","",IFERROR(INDEX(강사DB!$D$4:$D$53,MATCH($M9,강사DB!$A$4:$A$53,0)),"")) | Z9: =IF($B9<>"결제완료","",IF(OR($Y9="",$J9=""),"",$Y9*$J9+MAX(0,N($K9)-1)*설정!$J$7)) | AA9: =IF(AND($D9<>"",$B9="결제완료"),N($N9),"") | AB9: =IF($D9="","",IF($F9<>"",$F9,$D9)&IF($B9="상담중"," (상담)","")) | AC9: =IF(AND($D9<>"",OR($B9="결제완료",$B9="상담중")),1,0) -> 0 | AD9: =IF(OR($Z9="",$U9=""),0,IFERROR(IF(COUNTIFS(INDEX(g_grid,0,2*MATCH($M9,강사DB!$A$4:$A$15,0)),"<>",g_s,"<="&$U9,g_e,">="&$U9)>0,1,0),0)) -> 0 | AF9: =IF(AND($D9<>"",$B9="결제완료",$T9="대여"),설정!$J$5,"") | AG9: =IF($D9="","",IF(AND($E9="",$R9=""),$AB9,"☎ "&IF($E9="","-",$E9)&IF($R9<>""," ※ "&$R9,"")&IF($B9="상담중"," (상담)",""))) | AH9: =IF(AND($D9<>"",$B9="결제완료",$O9="스마트스토어"),ROUND(N($N9)*설정!$J$6,0),"") | AI9: =IF($D9="","",ROW()) | AJ9: =IF(OR($AC9<>1,$M9=""),0,IF(ISNUMBER(SEARCH("퇴사",IFERROR(INDEX(강사DB!$G$4:$G$53,MATCH($M9,강사DB!$A$4:$A$53,0)),""))),1,0)) -> 0
A10: =IF($D10="","",COUNTA($D$5:$D10)) | J10: =IF(OR($V10="",$W10=""),"",ROUND(($W10-$V10)/60,2)) | K10: =IF($F10="","",LEN($F10)-LEN(SUBSTITUTE($F10,",",""))+1) | L10: =IF($K10="","","1:"&$K10) | S10: =IF(OR($AC10=0,$U10="",$M10="",$V10="",$W10=""),"",IF(COUNTIFS(m_teacher,$M10,m_date,$U10,m_active,1,m_start,"<"&$W10,m_end,">"&$V10)>1,"충돌","")) | U10: =IF($G10="","",IFERROR(IF(ISNUMBER($G10),IF($G10>19000000,DATE(INT($G10/10000),MOD(INT($G10/100),100),MOD($G10,100)),INT($G10)),IF(LEN(SUBSTITUTE(SUBSTITUTE(SUBSTITUTE(TRIM($G10),"-",""),".",""),"/",""))=8,DATE(VALUE(LEFT(SUBSTITUTE(SUBSTITUTE(SUBSTITUTE(TRIM($G10),"-",""),".",""),"/",""),4)),VALUE(MID(SUBSTITUTE(SUBSTITUTE(SUBSTITUTE(TRIM($G10),"-",""),".",""),"/",""),5,2)),VALUE(RIGHT(SUBSTITUTE(SUBSTITUTE(SUBSTITUTE(TRIM($G10),"-",""),".",""),"/",""),2))),DATEVALUE($G10))),"")) | V10: =IF($H10="","",IFERROR(IF(IF(ISNUMBER($H10),$H10,IFERROR(TIMEVALUE($H10),VALUE($H10)))>=100,INT(IF(ISNUMBER($H10),$H10,IFERROR(TIMEVALUE($H10),VALUE($H10)))/100)*60+MOD(IF(ISNUMBER($H10),$H10,IFERROR(TIMEVALUE($H10),VALUE($H10))),100),IF(IF(ISNUMBER($H10),$H10,IFERROR(TIMEVALUE($H10),VALUE($H10)))>=1,ROUND(IF(ISNUMBER($H10),$H10,IFERROR(TIMEVALUE($H10),VALUE($H10)))*60,0),ROUND(MOD(IF(ISNUMBER($H10),$H10,IFERROR(TIMEVALUE($H10),VALUE($H10))),1)*1440,0))),"")) | W10: =IF($I10="","",IFERROR(IF(IF(ISNUMBER($I10),$I10,IFERROR(TIMEVALUE($I10),VALUE($I10)))>=100,INT(IF(ISNUMBER($I10),$I10,IFERROR(TIMEVALUE($I10),VALUE($I10)))/100)*60+MOD(IF(ISNUMBER($I10),$I10,IFERROR(TIMEVALUE($I10),VALUE($I10))),100),IF(IF(ISNUMBER($I10),$I10,IFERROR(TIMEVALUE($I10),VALUE($I10)))>=1,ROUND(IF(ISNUMBER($I10),$I10,IFERROR(TIMEVALUE($I10),VALUE($I10)))*60,0),ROUND(MOD(IF(ISNUMBER($I10),$I10,IFERROR(TIMEVALUE($I10),VALUE($I10))),1)*1440,0))),"")) | X10: =IF($P10="","",IFERROR(IF(ISNUMBER($P10),IF($P10>19000000,DATE(INT($P10/10000),MOD(INT($P10/100),100),MOD($P10,100)),INT($P10)),IF(LEN(SUBSTITUTE(SUBSTITUTE(SUBSTITUTE(TRIM($P10),"-",""),".",""),"/",""))=8,DATE(VALUE(LEFT(SUBSTITUTE(SUBSTITUTE(SUBSTITUTE(TRIM($P10),"-",""),".",""),"/",""),4)),VALUE(MID(SUBSTITUTE(SUBSTITUTE(SUBSTITUTE(TRIM($P10),"-",""),".",""),"/",""),5,2)),VALUE(RIGHT(SUBSTITUTE(SUBSTITUTE(SUBSTITUTE(TRIM($P10),"-",""),".",""),"/",""),2))),DATEVALUE($P10))),"")) | Y10: =IF($M10="","",IFERROR(INDEX(강사DB!$D$4:$D$53,MATCH($M10,강사DB!$A$4:$A$53,0)),"")) | Z10: =IF($B10<>"결제완료","",IF(OR($Y10="",$J10=""),"",$Y10*$J10+MAX(0,N($K10)-1)*설정!$J$7)) | AA10: =IF(AND($D10<>"",$B10="결제완료"),N($N10),"") | AB10: =IF($D10="","",IF($F10<>"",$F10,$D10)&IF($B10="상담중"," (상담)","")) | AC10: =IF(AND($D10<>"",OR($B10="결제완료",$B10="상담중")),1,0) -> 0 | AD10: =IF(OR($Z10="",$U10=""),0,IFERROR(IF(COUNTIFS(INDEX(g_grid,0,2*MATCH($M10,강사DB!$A$4:$A$15,0)),"<>",g_s,"<="&$U10,g_e,">="&$U10)>0,1,0),0)) -> 0 | AF10: =IF(AND($D10<>"",$B10="결제완료",$T10="대여"),설정!$J$5,"") | AG10: =IF($D10="","",IF(AND($E10="",$R10=""),$AB10,"☎ "&IF($E10="","-",$E10)&IF($R10<>""," ※ "&$R10,"")&IF($B10="상담중"," (상담)",""))) | AH10: =IF(AND($D10<>"",$B10="결제완료",$O10="스마트스토어"),ROUND(N($N10)*설정!$J$6,0),"") | AI10: =IF($D10="","",ROW()) | AJ10: =IF(OR($AC10<>1,$M10=""),0,IF(ISNUMBER(SEARCH("퇴사",IFERROR(INDEX(강사DB!$G$4:$G$53,MATCH($M10,강사DB!$A$4:$A$53,0)),""))),1,0)) -> 0
A11: =IF($D11="","",COUNTA($D$5:$D11)) | J11: =IF(OR($V11="",$W11=""),"",ROUND(($W11-$V11)/60,2)) | K11: =IF($F11="","",LEN($F11)-LEN(SUBSTITUTE($F11,",",""))+1) | L11: =IF($K11="","","1:"&$K11) | S11: =IF(OR($AC11=0,$U11="",$M11="",$V11="",$W11=""),"",IF(COUNTIFS(m_teacher,$M11,m_date,$U11,m_active,1,m_start,"<"&$W11,m_end,">"&$V11)>1,"충돌","")) | U11: =IF($G11="","",IFERROR(IF(ISNUMBER($G11),IF($G11>19000000,DATE(INT($G11/10000),MOD(INT($G11/100),100),MOD($G11,100)),INT($G11)),IF(LEN(SUBSTITUTE(SUBSTITUTE(SUBSTITUTE(TRIM($G11),"-",""),".",""),"/",""))=8,DATE(VALUE(LEFT(SUBSTITUTE(SUBSTITUTE(SUBSTITUTE(TRIM($G11),"-",""),".",""),"/",""),4)),VALUE(MID(SUBSTITUTE(SUBSTITUTE(SUBSTITUTE(TRIM($G11),"-",""),".",""),"/",""),5,2)),VALUE(RIGHT(SUBSTITUTE(SUBSTITUTE(SUBSTITUTE(TRIM($G11),"-",""),".",""),"/",""),2))),DATEVALUE($G11))),"")) | V11: =IF($H11="","",IFERROR(IF(IF(ISNUMBER($H11),$H11,IFERROR(TIMEVALUE($H11),VALUE($H11)))>=100,INT(IF(ISNUMBER($H11),$H11,IFERROR(TIMEVALUE($H11),VALUE($H11)))/100)*60+MOD(IF(ISNUMBER($H11),$H11,IFERROR(TIMEVALUE($H11),VALUE($H11))),100),IF(IF(ISNUMBER($H11),$H11,IFERROR(TIMEVALUE($H11),VALUE($H11)))>=1,ROUND(IF(ISNUMBER($H11),$H11,IFERROR(TIMEVALUE($H11),VALUE($H11)))*60,0),ROUND(MOD(IF(ISNUMBER($H11),$H11,IFERROR(TIMEVALUE($H11),VALUE($H11))),1)*1440,0))),"")) | W11: =IF($I11="","",IFERROR(IF(IF(ISNUMBER($I11),$I11,IFERROR(TIMEVALUE($I11),VALUE($I11)))>=100,INT(IF(ISNUMBER($I11),$I11,IFERROR(TIMEVALUE($I11),VALUE($I11)))/100)*60+MOD(IF(ISNUMBER($I11),$I11,IFERROR(TIMEVALUE($I11),VALUE($I11))),100),IF(IF(ISNUMBER($I11),$I11,IFERROR(TIMEVALUE($I11),VALUE($I11)))>=1,ROUND(IF(ISNUMBER($I11),$I11,IFERROR(TIMEVALUE($I11),VALUE($I11)))*60,0),ROUND(MOD(IF(ISNUMBER($I11),$I11,IFERROR(TIMEVALUE($I11),VALUE($I11))),1)*1440,0))),"")) | X11: =IF($P11="","",IFERROR(IF(ISNUMBER($P11),IF($P11>19000000,DATE(INT($P11/10000),MOD(INT($P11/100),100),MOD($P11,100)),INT($P11)),IF(LEN(SUBSTITUTE(SUBSTITUTE(SUBSTITUTE(TRIM($P11),"-",""),".",""),"/",""))=8,DATE(VALUE(LEFT(SUBSTITUTE(SUBSTITUTE(SUBSTITUTE(TRIM($P11),"-",""),".",""),"/",""),4)),VALUE(MID(SUBSTITUTE(SUBSTITUTE(SUBSTITUTE(TRIM($P11),"-",""),".",""),"/",""),5,2)),VALUE(RIGHT(SUBSTITUTE(SUBSTITUTE(SUBSTITUTE(TRIM($P11),"-",""),".",""),"/",""),2))),DATEVALUE($P11))),"")) | Y11: =IF($M11="","",IFERROR(INDEX(강사DB!$D$4:$D$53,MATCH($M11,강사DB!$A$4:$A$53,0)),"")) | Z11: =IF($B11<>"결제완료","",IF(OR($Y11="",$J11=""),"",$Y11*$J11+MAX(0,N($K11)-1)*설정!$J$7)) | AA11: =IF(AND($D11<>"",$B11="결제완료"),N($N11),"") | AB11: =IF($D11="","",IF($F11<>"",$F11,$D11)&IF($B11="상담중"," (상담)","")) | AC11: =IF(AND($D11<>"",OR($B11="결제완료",$B11="상담중")),1,0) -> 0 | AD11: =IF(OR($Z11="",$U11=""),0,IFERROR(IF(COUNTIFS(INDEX(g_grid,0,2*MATCH($M11,강사DB!$A$4:$A$15,0)),"<>",g_s,"<="&$U11,g_e,">="&$U11)>0,1,0),0)) -> 0 | AF11: =IF(AND($D11<>"",$B11="결제완료",$T11="대여"),설정!$J$5,"") | AG11: =IF($D11="","",IF(AND($E11="",$R11=""),$AB11,"☎ "&IF($E11="","-",$E11)&IF($R11<>""," ※ "&$R11,"")&IF($B11="상담중"," (상담)",""))) | AH11: =IF(AND($D11<>"",$B11="결제완료",$O11="스마트스토어"),ROUND(N($N11)*설정!$J$6,0),"") | AI11: =IF($D11="","",ROW()) | AJ11: =IF(OR($AC11<>1,$M11=""),0,IF(ISNUMBER(SEARCH("퇴사",IFERROR(INDEX(강사DB!$G$4:$G$53,MATCH($M11,강사DB!$A$4:$A$53,0)),""))),1,0)) -> 0
A12: =IF($D12="","",COUNTA($D$5:$D12)) | J12: =IF(OR($V12="",$W12=""),"",ROUND(($W12-$V12)/60,2)) | K12: =IF($F12="","",LEN($F12)-LEN(SUBSTITUTE($F12,",",""))+1) | L12: =IF($K12="","","1:"&$K12) | S12: =IF(OR($AC12=0,$U12="",$M12="",$V12="",$W12=""),"",IF(COUNTIFS(m_teacher,$M12,m_date,$U12,m_active,1,m_start,"<"&$W12,m_end,">"&$V12)>1,"충돌","")) | U12: =IF($G12="","",IFERROR(IF(ISNUMBER($G12),IF($G12>19000000,DATE(INT($G12/10000),MOD(INT($G12/100),100),MOD($G12,100)),INT($G12)),IF(LEN(SUBSTITUTE(SUBSTITUTE(SUBSTITUTE(TRIM($G12),"-",""),".",""),"/",""))=8,DATE(VALUE(LEFT(SUBSTITUTE(SUBSTITUTE(SUBSTITUTE(TRIM($G12),"-",""),".",""),"/",""),4)),VALUE(MID(SUBSTITUTE(SUBSTITUTE(SUBSTITUTE(TRIM($G12),"-",""),".",""),"/",""),5,2)),VALUE(RIGHT(SUBSTITUTE(SUBSTITUTE(SUBSTITUTE(TRIM($G12),"-",""),".",""),"/",""),2))),DATEVALUE($G12))),"")) | V12: =IF($H12="","",IFERROR(IF(IF(ISNUMBER($H12),$H12,IFERROR(TIMEVALUE($H12),VALUE($H12)))>=100,INT(IF(ISNUMBER($H12),$H12,IFERROR(TIMEVALUE($H12),VALUE($H12)))/100)*60+MOD(IF(ISNUMBER($H12),$H12,IFERROR(TIMEVALUE($H12),VALUE($H12))),100),IF(IF(ISNUMBER($H12),$H12,IFERROR(TIMEVALUE($H12),VALUE($H12)))>=1,ROUND(IF(ISNUMBER($H12),$H12,IFERROR(TIMEVALUE($H12),VALUE($H12)))*60,0),ROUND(MOD(IF(ISNUMBER($H12),$H12,IFERROR(TIMEVALUE($H12),VALUE($H12))),1)*1440,0))),"")) | W12: =IF($I12="","",IFERROR(IF(IF(ISNUMBER($I12),$I12,IFERROR(TIMEVALUE($I12),VALUE($I12)))>=100,INT(IF(ISNUMBER($I12),$I12,IFERROR(TIMEVALUE($I12),VALUE($I12)))/100)*60+MOD(IF(ISNUMBER($I12),$I12,IFERROR(TIMEVALUE($I12),VALUE($I12))),100),IF(IF(ISNUMBER($I12),$I12,IFERROR(TIMEVALUE($I12),VALUE($I12)))>=1,ROUND(IF(ISNUMBER($I12),$I12,IFERROR(TIMEVALUE($I12),VALUE($I12)))*60,0),ROUND(MOD(IF(ISNUMBER($I12),$I12,IFERROR(TIMEVALUE($I12),VALUE($I12))),1)*1440,0))),"")) | X12: =IF($P12="","",IFERROR(IF(ISNUMBER($P12),IF($P12>19000000,DATE(INT($P12/10000),MOD(INT($P12/100),100),MOD($P12,100)),INT($P12)),IF(LEN(SUBSTITUTE(SUBSTITUTE(SUBSTITUTE(TRIM($P12),"-",""),".",""),"/",""))=8,DATE(VALUE(LEFT(SUBSTITUTE(SUBSTITUTE(SUBSTITUTE(TRIM($P12),"-",""),".",""),"/",""),4)),VALUE(MID(SUBSTITUTE(SUBSTITUTE(SUBSTITUTE(TRIM($P12),"-",""),".",""),"/",""),5,2)),VALUE(RIGHT(SUBSTITUTE(SUBSTITUTE(SUBSTITUTE(TRIM($P12),"-",""),".",""),"/",""),2))),DATEVALUE($P12))),"")) | Y12: =IF($M12="","",IFERROR(INDEX(강사DB!$D$4:$D$53,MATCH($M12,강사DB!$A$4:$A$53,0)),"")) | Z12: =IF($B12<>"결제완료","",IF(OR($Y12="",$J12=""),"",$Y12*$J12+MAX(0,N($K12)-1)*설정!$J$7)) | AA12: =IF(AND($D12<>"",$B12="결제완료"),N($N12),"") | AB12: =IF($D12="","",IF($F12<>"",$F12,$D12)&IF($B12="상담중"," (상담)","")) | AC12: =IF(AND($D12<>"",OR($B12="결제완료",$B12="상담중")),1,0) -> 0 | AD12: =IF(OR($Z12="",$U12=""),0,IFERROR(IF(COUNTIFS(INDEX(g_grid,0,2*MATCH($M12,강사DB!$A$4:$A$15,0)),"<>",g_s,"<="&$U12,g_e,">="&$U12)>0,1,0),0)) -> 0 | AF12: =IF(AND($D12<>"",$B12="결제완료",$T12="대여"),설정!$J$5,"") | AG12: =IF($D12="","",IF(AND($E12="",$R12=""),$AB12,"☎ "&IF($E12="","-",$E12)&IF($R12<>""," ※ "&$R12,"")&IF($B12="상담중"," (상담)",""))) | AH12: =IF(AND($D12<>"",$B12="결제완료",$O12="스마트스토어"),ROUND(N($N12)*설정!$J$6,0),"") | AI12: =IF($D12="","",ROW()) | AJ12: =IF(OR($AC12<>1,$M12=""),0,IF(ISNUMBER(SEARCH("퇴사",IFERROR(INDEX(강사DB!$G$4:$G$53,MATCH($M12,강사DB!$A$4:$A$53,0)),""))),1,0)) -> 0
A13: =IF($D13="","",COUNTA($D$5:$D13)) | J13: =IF(OR($V13="",$W13=""),"",ROUND(($W13-$V13)/60,2)) | K13: =IF($F13="","",LEN($F13)-LEN(SUBSTITUTE($F13,",",""))+1) | L13: =IF($K13="","","1:"&$K13) | S13: =IF(OR($AC13=0,$U13="",$M13="",$V13="",$W13=""),"",IF(COUNTIFS(m_teacher,$M13,m_date,$U13,m_active,1,m_start,"<"&$W13,m_end,">"&$V13)>1,"충돌","")) | U13: =IF($G13="","",IFERROR(IF(ISNUMBER($G13),IF($G13>19000000,DATE(INT($G13/10000),MOD(INT($G13/100),100),MOD($G13,100)),INT($G13)),IF(LEN(SUBSTITUTE(SUBSTITUTE(SUBSTITUTE(TRIM($G13),"-",""),".",""),"/",""))=8,DATE(VALUE(LEFT(SUBSTITUTE(SUBSTITUTE(SUBSTITUTE(TRIM($G13),"-",""),".",""),"/",""),4)),VALUE(MID(SUBSTITUTE(SUBSTITUTE(SUBSTITUTE(TRIM($G13),"-",""),".",""),"/",""),5,2)),VALUE(RIGHT(SUBSTITUTE(SUBSTITUTE(SUBSTITUTE(TRIM($G13),"-",""),".",""),"/",""),2))),DATEVALUE($G13))),"")) | V13: =IF($H13="","",IFERROR(IF(IF(ISNUMBER($H13),$H13,IFERROR(TIMEVALUE($H13),VALUE($H13)))>=100,INT(IF(ISNUMBER($H13),$H13,IFERROR(TIMEVALUE($H13),VALUE($H13)))/100)*60+MOD(IF(ISNUMBER($H13),$H13,IFERROR(TIMEVALUE($H13),VALUE($H13))),100),IF(IF(ISNUMBER($H13),$H13,IFERROR(TIMEVALUE($H13),VALUE($H13)))>=1,ROUND(IF(ISNUMBER($H13),$H13,IFERROR(TIMEVALUE($H13),VALUE($H13)))*60,0),ROUND(MOD(IF(ISNUMBER($H13),$H13,IFERROR(TIMEVALUE($H13),VALUE($H13))),1)*1440,0))),"")) | W13: =IF($I13="","",IFERROR(IF(IF(ISNUMBER($I13),$I13,IFERROR(TIMEVALUE($I13),VALUE($I13)))>=100,INT(IF(ISNUMBER($I13),$I13,IFERROR(TIMEVALUE($I13),VALUE($I13)))/100)*60+MOD(IF(ISNUMBER($I13),$I13,IFERROR(TIMEVALUE($I13),VALUE($I13))),100),IF(IF(ISNUMBER($I13),$I13,IFERROR(TIMEVALUE($I13),VALUE($I13)))>=1,ROUND(IF(ISNUMBER($I13),$I13,IFERROR(TIMEVALUE($I13),VALUE($I13)))*60,0),ROUND(MOD(IF(ISNUMBER($I13),$I13,IFERROR(TIMEVALUE($I13),VALUE($I13))),1)*1440,0))),"")) | X13: =IF($P13="","",IFERROR(IF(ISNUMBER($P13),IF($P13>19000000,DATE(INT($P13/10000),MOD(INT($P13/100),100),MOD($P13,100)),INT($P13)),IF(LEN(SUBSTITUTE(SUBSTITUTE(SUBSTITUTE(TRIM($P13),"-",""),".",""),"/",""))=8,DATE(VALUE(LEFT(SUBSTITUTE(SUBSTITUTE(SUBSTITUTE(TRIM($P13),"-",""),".",""),"/",""),4)),VALUE(MID(SUBSTITUTE(SUBSTITUTE(SUBSTITUTE(TRIM($P13),"-",""),".",""),"/",""),5,2)),VALUE(RIGHT(SUBSTITUTE(SUBSTITUTE(SUBSTITUTE(TRIM($P13),"-",""),".",""),"/",""),2))),DATEVALUE($P13))),"")) | Y13: =IF($M13="","",IFERROR(INDEX(강사DB!$D$4:$D$53,MATCH($M13,강사DB!$A$4:$A$53,0)),"")) | Z13: =IF($B13<>"결제완료","",IF(OR($Y13="",$J13=""),"",$Y13*$J13+MAX(0,N($K13)-1)*설정!$J$7)) | AA13: =IF(AND($D13<>"",$B13="결제완료"),N($N13),"") | AB13: =IF($D13="","",IF($F13<>"",$F13,$D13)&IF($B13="상담중"," (상담)","")) | AC13: =IF(AND($D13<>"",OR($B13="결제완료",$B13="상담중")),1,0) -> 0 | AD13: =IF(OR($Z13="",$U13=""),0,IFERROR(IF(COUNTIFS(INDEX(g_grid,0,2*MATCH($M13,강사DB!$A$4:$A$15,0)),"<>",g_s,"<="&$U13,g_e,">="&$U13)>0,1,0),0)) -> 0 | AF13: =IF(AND($D13<>"",$B13="결제완료",$T13="대여"),설정!$J$5,"") | AG13: =IF($D13="","",IF(AND($E13="",$R13=""),$AB13,"☎ "&IF($E13="","-",$E13)&IF($R13<>""," ※ "&$R13,"")&IF($B13="상담중"," (상담)",""))) | AH13: =IF(AND($D13<>"",$B13="결제완료",$O13="스마트스토어"),ROUND(N($N13)*설정!$J$6,0),"") | AI13: =IF($D13="","",ROW()) | AJ13: =IF(OR($AC13<>1,$M13=""),0,IF(ISNUMBER(SEARCH("퇴사",IFERROR(INDEX(강사DB!$G$4:$G$53,MATCH($M13,강사DB!$A$4:$A$53,0)),""))),1,0)) -> 0
A14: =IF($D14="","",COUNTA($D$5:$D14)) | J14: =IF(OR($V14="",$W14=""),"",ROUND(($W14-$V14)/60,2)) | K14: =IF($F14="","",LEN($F14)-LEN(SUBSTITUTE($F14,",",""))+1) | L14: =IF($K14="","","1:"&$K14) | S14: =IF(OR($AC14=0,$U14="",$M14="",$V14="",$W14=""),"",IF(COUNTIFS(m_teacher,$M14,m_date,$U14,m_active,1,m_start,"<"&$W14,m_end,">"&$V14)>1,"충돌","")) | U14: =IF($G14="","",IFERROR(IF(ISNUMBER($G14),IF($G14>19000000,DATE(INT($G14/10000),MOD(INT($G14/100),100),MOD($G14,100)),INT($G14)),IF(LEN(SUBSTITUTE(SUBSTITUTE(SUBSTITUTE(TRIM($G14),"-",""),".",""),"/",""))=8,DATE(VALUE(LEFT(SUBSTITUTE(SUBSTITUTE(SUBSTITUTE(TRIM($G14),"-",""),".",""),"/",""),4)),VALUE(MID(SUBSTITUTE(SUBSTITUTE(SUBSTITUTE(TRIM($G14),"-",""),".",""),"/",""),5,2)),VALUE(RIGHT(SUBSTITUTE(SUBSTITUTE(SUBSTITUTE(TRIM($G14),"-",""),".",""),"/",""),2))),DATEVALUE($G14))),"")) | V14: =IF($H14="","",IFERROR(IF(IF(ISNUMBER($H14),$H14,IFERROR(TIMEVALUE($H14),VALUE($H14)))>=100,INT(IF(ISNUMBER($H14),$H14,IFERROR(TIMEVALUE($H14),VALUE($H14)))/100)*60+MOD(IF(ISNUMBER($H14),$H14,IFERROR(TIMEVALUE($H14),VALUE($H14))),100),IF(IF(ISNUMBER($H14),$H14,IFERROR(TIMEVALUE($H14),VALUE($H14)))>=1,ROUND(IF(ISNUMBER($H14),$H14,IFERROR(TIMEVALUE($H14),VALUE($H14)))*60,0),ROUND(MOD(IF(ISNUMBER($H14),$H14,IFERROR(TIMEVALUE($H14),VALUE($H14))),1)*1440,0))),"")) | W14: =IF($I14="","",IFERROR(IF(IF(ISNUMBER($I14),$I14,IFERROR(TIMEVALUE($I14),VALUE($I14)))>=100,INT(IF(ISNUMBER($I14),$I14,IFERROR(TIMEVALUE($I14),VALUE($I14)))/100)*60+MOD(IF(ISNUMBER($I14),$I14,IFERROR(TIMEVALUE($I14),VALUE($I14))),100),IF(IF(ISNUMBER($I14),$I14,IFERROR(TIMEVALUE($I14),VALUE($I14)))>=1,ROUND(IF(ISNUMBER($I14),$I14,IFERROR(TIMEVALUE($I14),VALUE($I14)))*60,0),ROUND(MOD(IF(ISNUMBER($I14),$I14,IFERROR(TIMEVALUE($I14),VALUE($I14))),1)*1440,0))),"")) | X14: =IF($P14="","",IFERROR(IF(ISNUMBER($P14),IF($P14>19000000,DATE(INT($P14/10000),MOD(INT($P14/100),100),MOD($P14,100)),INT($P14)),IF(LEN(SUBSTITUTE(SUBSTITUTE(SUBSTITUTE(TRIM($P14),"-",""),".",""),"/",""))=8,DATE(VALUE(LEFT(SUBSTITUTE(SUBSTITUTE(SUBSTITUTE(TRIM($P14),"-",""),".",""),"/",""),4)),VALUE(MID(SUBSTITUTE(SUBSTITUTE(SUBSTITUTE(TRIM($P14),"-",""),".",""),"/",""),5,2)),VALUE(RIGHT(SUBSTITUTE(SUBSTITUTE(SUBSTITUTE(TRIM($P14),"-",""),".",""),"/",""),2))),DATEVALUE($P14))),"")) | Y14: =IF($M14="","",IFERROR(INDEX(강사DB!$D$4:$D$53,MATCH($M14,강사DB!$A$4:$A$53,0)),"")) | Z14: =IF($B14<>"결제완료","",IF(OR($Y14="",$J14=""),"",$Y14*$J14+MAX(0,N($K14)-1)*설정!$J$7)) | AA14: =IF(AND($D14<>"",$B14="결제완료"),N($N14),"") | AB14: =IF($D14="","",IF($F14<>"",$F14,$D14)&IF($B14="상담중"," (상담)","")) | AC14: =IF(AND($D14<>"",OR($B14="결제완료",$B14="상담중")),1,0) -> 0 | AD14: =IF(OR($Z14="",$U14=""),0,IFERROR(IF(COUNTIFS(INDEX(g_grid,0,2*MATCH($M14,강사DB!$A$4:$A$15,0)),"<>",g_s,"<="&$U14,g_e,">="&$U14)>0,1,0),0)) -> 0 | AF14: =IF(AND($D14<>"",$B14="결제완료",$T14="대여"),설정!$J$5,"") | AG14: =IF($D14="","",IF(AND($E14="",$R14=""),$AB14,"☎ "&IF($E14="","-",$E14)&IF($R14<>""," ※ "&$R14,"")&IF($B14="상담중"," (상담)",""))) | AH14: =IF(AND($D14<>"",$B14="결제완료",$O14="스마트스토어"),ROUND(N($N14)*설정!$J$6,0),"") | AI14: =IF($D14="","",ROW()) | AJ14: =IF(OR($AC14<>1,$M14=""),0,IF(ISNUMBER(SEARCH("퇴사",IFERROR(INDEX(강사DB!$G$4:$G$53,MATCH($M14,강사DB!$A$4:$A$53,0)),""))),1,0)) -> 0
A15: =IF($D15="","",COUNTA($D$5:$D15)) | J15: =IF(OR($V15="",$W15=""),"",ROUND(($W15-$V15)/60,2)) | K15: =IF($F15="","",LEN($F15)-LEN(SUBSTITUTE($F15,",",""))+1) | L15: =IF($K15="","","1:"&$K15) | S15: =IF(OR($AC15=0,$U15="",$M15="",$V15="",$W15=""),"",IF(COUNTIFS(m_teacher,$M15,m_date,$U15,m_active,1,m_start,"<"&$W15,m_end,">"&$V15)>1,"충돌","")) | U15: =IF($G15="","",IFERROR(IF(ISNUMBER($G15),IF($G15>19000000,DATE(INT($G15/10000),MOD(INT($G15/100),100),MOD($G15,100)),INT($G15)),IF(LEN(SUBSTITUTE(SUBSTITUTE(SUBSTITUTE(TRIM($G15),"-",""),".",""),"/",""))=8,DATE(VALUE(LEFT(SUBSTITUTE(SUBSTITUTE(SUBSTITUTE(TRIM($G15),"-",""),".",""),"/",""),4)),VALUE(MID(SUBSTITUTE(SUBSTITUTE(SUBSTITUTE(TRIM($G15),"-",""),".",""),"/",""),5,2)),VALUE(RIGHT(SUBSTITUTE(SUBSTITUTE(SUBSTITUTE(TRIM($G15),"-",""),".",""),"/",""),2))),DATEVALUE($G15))),"")) | V15: =IF($H15="","",IFERROR(IF(IF(ISNUMBER($H15),$H15,IFERROR(TIMEVALUE($H15),VALUE($H15)))>=100,INT(IF(ISNUMBER($H15),$H15,IFERROR(TIMEVALUE($H15),VALUE($H15)))/100)*60+MOD(IF(ISNUMBER($H15),$H15,IFERROR(TIMEVALUE($H15),VALUE($H15))),100),IF(IF(ISNUMBER($H15),$H15,IFERROR(TIMEVALUE($H15),VALUE($H15)))>=1,ROUND(IF(ISNUMBER($H15),$H15,IFERROR(TIMEVALUE($H15),VALUE($H15)))*60,0),ROUND(MOD(IF(ISNUMBER($H15),$H15,IFERROR(TIMEVALUE($H15),VALUE($H15))),1)*1440,0))),"")) | W15: =IF($I15="","",IFERROR(IF(IF(ISNUMBER($I15),$I15,IFERROR(TIMEVALUE($I15),VALUE($I15)))>=100,INT(IF(ISNUMBER($I15),$I15,IFERROR(TIMEVALUE($I15),VALUE($I15)))/100)*60+MOD(IF(ISNUMBER($I15),$I15,IFERROR(TIMEVALUE($I15),VALUE($I15))),100),IF(IF(ISNUMBER($I15),$I15,IFERROR(TIMEVALUE($I15),VALUE($I15)))>=1,ROUND(IF(ISNUMBER($I15),$I15,IFERROR(TIMEVALUE($I15),VALUE($I15)))*60,0),ROUND(MOD(IF(ISNUMBER($I15),$I15,IFERROR(TIMEVALUE($I15),VALUE($I15))),1)*1440,0))),"")) | X15: =IF($P15="","",IFERROR(IF(ISNUMBER($P15),IF($P15>19000000,DATE(INT($P15/10000),MOD(INT($P15/100),100),MOD($P15,100)),INT($P15)),IF(LEN(SUBSTITUTE(SUBSTITUTE(SUBSTITUTE(TRIM($P15),"-",""),".",""),"/",""))=8,DATE(VALUE(LEFT(SUBSTITUTE(SUBSTITUTE(SUBSTITUTE(TRIM($P15),"-",""),".",""),"/",""),4)),VALUE(MID(SUBSTITUTE(SUBSTITUTE(SUBSTITUTE(TRIM($P15),"-",""),".",""),"/",""),5,2)),VALUE(RIGHT(SUBSTITUTE(SUBSTITUTE(SUBSTITUTE(TRIM($P15),"-",""),".",""),"/",""),2))),DATEVALUE($P15))),"")) | Y15: =IF($M15="","",IFERROR(INDEX(강사DB!$D$4:$D$53,MATCH($M15,강사DB!$A$4:$A$53,0)),"")) | Z15: =IF($B15<>"결제완료","",IF(OR($Y15="",$J15=""),"",$Y15*$J15+MAX(0,N($K15)-1)*설정!$J$7)) | AA15: =IF(AND($D15<>"",$B15="결제완료"),N($N15),"") | AB15: =IF($D15="","",IF($F15<>"",$F15,$D15)&IF($B15="상담중"," (상담)","")) | AC15: =IF(AND($D15<>"",OR($B15="결제완료",$B15="상담중")),1,0) -> 0 | AD15: =IF(OR($Z15="",$U15=""),0,IFERROR(IF(COUNTIFS(INDEX(g_grid,0,2*MATCH($M15,강사DB!$A$4:$A$15,0)),"<>",g_s,"<="&$U15,g_e,">="&$U15)>0,1,0),0)) -> 0 | AF15: =IF(AND($D15<>"",$B15="결제완료",$T15="대여"),설정!$J$5,"") | AG15: =IF($D15="","",IF(AND($E15="",$R15=""),$AB15,"☎ "&IF($E15="","-",$E15)&IF($R15<>""," ※ "&$R15,"")&IF($B15="상담중"," (상담)",""))) | AH15: =IF(AND($D15<>"",$B15="결제완료",$O15="스마트스토어"),ROUND(N($N15)*설정!$J$6,0),"") | AI15: =IF($D15="","",ROW()) | AJ15: =IF(OR($AC15<>1,$M15=""),0,IF(ISNUMBER(SEARCH("퇴사",IFERROR(INDEX(강사DB!$G$4:$G$53,MATCH($M15,강사DB!$A$4:$A$53,0)),""))),1,0)) -> 0
A16: =IF($D16="","",COUNTA($D$5:$D16)) | J16: =IF(OR($V16="",$W16=""),"",ROUND(($W16-$V16)/60,2)) | K16: =IF($F16="","",LEN($F16)-LEN(SUBSTITUTE($F16,",",""))+1) | L16: =IF($K16="","","1:"&$K16) | S16: =IF(OR($AC16=0,$U16="",$M16="",$V16="",$W16=""),"",IF(COUNTIFS(m_teacher,$M16,m_date,$U16,m_active,1,m_start,"<"&$W16,m_end,">"&$V16)>1,"충돌","")) | U16: =IF($G16="","",IFERROR(IF(ISNUMBER($G16),IF($G16>19000000,DATE(INT($G16/10000),MOD(INT($G16/100),100),MOD($G16,100)),INT($G16)),IF(LEN(SUBSTITUTE(SUBSTITUTE(SUBSTITUTE(TRIM($G16),"-",""),".",""),"/",""))=8,DATE(VALUE(LEFT(SUBSTITUTE(SUBSTITUTE(SUBSTITUTE(TRIM($G16),"-",""),".",""),"/",""),4)),VALUE(MID(SUBSTITUTE(SUBSTITUTE(SUBSTITUTE(TRIM($G16),"-",""),".",""),"/",""),5,2)),VALUE(RIGHT(SUBSTITUTE(SUBSTITUTE(SUBSTITUTE(TRIM($G16),"-",""),".",""),"/",""),2))),DATEVALUE($G16))),"")) | V16: =IF($H16="","",IFERROR(IF(IF(ISNUMBER($H16),$H16,IFERROR(TIMEVALUE($H16),VALUE($H16)))>=100,INT(IF(ISNUMBER($H16),$H16,IFERROR(TIMEVALUE($H16),VALUE($H16)))/100)*60+MOD(IF(ISNUMBER($H16),$H16,IFERROR(TIMEVALUE($H16),VALUE($H16))),100),IF(IF(ISNUMBER($H16),$H16,IFERROR(TIMEVALUE($H16),VALUE($H16)))>=1,ROUND(IF(ISNUMBER($H16),$H16,IFERROR(TIMEVALUE($H16),VALUE($H16)))*60,0),ROUND(MOD(IF(ISNUMBER($H16),$H16,IFERROR(TIMEVALUE($H16),VALUE($H16))),1)*1440,0))),"")) | W16: =IF($I16="","",IFERROR(IF(IF(ISNUMBER($I16),$I16,IFERROR(TIMEVALUE($I16),VALUE($I16)))>=100,INT(IF(ISNUMBER($I16),$I16,IFERROR(TIMEVALUE($I16),VALUE($I16)))/100)*60+MOD(IF(ISNUMBER($I16),$I16,IFERROR(TIMEVALUE($I16),VALUE($I16))),100),IF(IF(ISNUMBER($I16),$I16,IFERROR(TIMEVALUE($I16),VALUE($I16)))>=1,ROUND(IF(ISNUMBER($I16),$I16,IFERROR(TIMEVALUE($I16),VALUE($I16)))*60,0),ROUND(MOD(IF(ISNUMBER($I16),$I16,IFERROR(TIMEVALUE($I16),VALUE($I16))),1)*1440,0))),"")) | X16: =IF($P16="","",IFERROR(IF(ISNUMBER($P16),IF($P16>19000000,DATE(INT($P16/10000),MOD(INT($P16/100),100),MOD($P16,100)),INT($P16)),IF(LEN(SUBSTITUTE(SUBSTITUTE(SUBSTITUTE(TRIM($P16),"-",""),".",""),"/",""))=8,DATE(VALUE(LEFT(SUBSTITUTE(SUBSTITUTE(SUBSTITUTE(TRIM($P16),"-",""),".",""),"/",""),4)),VALUE(MID(SUBSTITUTE(SUBSTITUTE(SUBSTITUTE(TRIM($P16),"-",""),".",""),"/",""),5,2)),VALUE(RIGHT(SUBSTITUTE(SUBSTITUTE(SUBSTITUTE(TRIM($P16),"-",""),".",""),"/",""),2))),DATEVALUE($P16))),"")) | Y16: =IF($M16="","",IFERROR(INDEX(강사DB!$D$4:$D$53,MATCH($M16,강사DB!$A$4:$A$53,0)),"")) | Z16: =IF($B16<>"결제완료","",IF(OR($Y16="",$J16=""),"",$Y16*$J16+MAX(0,N($K16)-1)*설정!$J$7)) | AA16: =IF(AND($D16<>"",$B16="결제완료"),N($N16),"") | AB16: =IF($D16="","",IF($F16<>"",$F16,$D16)&IF($B16="상담중"," (상담)","")) | AC16: =IF(AND($D16<>"",OR($B16="결제완료",$B16="상담중")),1,0) -> 0 | AD16: =IF(OR($Z16="",$U16=""),0,IFERROR(IF(COUNTIFS(INDEX(g_grid,0,2*MATCH($M16,강사DB!$A$4:$A$15,0)),"<>",g_s,"<="&$U16,g_e,">="&$U16)>0,1,0),0)) -> 0 | AF16: =IF(AND($D16<>"",$B16="결제완료",$T16="대여"),설정!$J$5,"") | AG16: =IF($D16="","",IF(AND($E16="",$R16=""),$AB16,"☎ "&IF($E16="","-",$E16)&IF($R16<>""," ※ "&$R16,"")&IF($B16="상담중"," (상담)",""))) | AH16: =IF(AND($D16<>"",$B16="결제완료",$O16="스마트스토어"),ROUND(N($N16)*설정!$J$6,0),"") | AI16: =IF($D16="","",ROW()) | AJ16: =IF(OR($AC16<>1,$M16=""),0,IF(ISNUMBER(SEARCH("퇴사",IFERROR(INDEX(강사DB!$G$4:$G$53,MATCH($M16,강사DB!$A$4:$A$53,0)),""))),1,0)) -> 0
A17: =IF($D17="","",COUNTA($D$5:$D17)) | J17: =IF(OR($V17="",$W17=""),"",ROUND(($W17-$V17)/60,2)) | K17: =IF($F17="","",LEN($F17)-LEN(SUBSTITUTE($F17,",",""))+1) | L17: =IF($K17="","","1:"&$K17) | S17: =IF(OR($AC17=0,$U17="",$M17="",$V17="",$W17=""),"",IF(COUNTIFS(m_teacher,$M17,m_date,$U17,m_active,1,m_start,"<"&$W17,m_end,">"&$V17)>1,"충돌","")) | U17: =IF($G17="","",IFERROR(IF(ISNUMBER($G17),IF($G17>19000000,DATE(INT($G17/10000),MOD(INT($G17/100),100),MOD($G17,100)),INT($G17)),IF(LEN(SUBSTITUTE(SUBSTITUTE(SUBSTITUTE(TRIM($G17),"-",""),".",""),"/",""))=8,DATE(VALUE(LEFT(SUBSTITUTE(SUBSTITUTE(SUBSTITUTE(TRIM($G17),"-",""),".",""),"/",""),4)),VALUE(MID(SUBSTITUTE(SUBSTITUTE(SUBSTITUTE(TRIM($G17),"-",""),".",""),"/",""),5,2)),VALUE(RIGHT(SUBSTITUTE(SUBSTITUTE(SUBSTITUTE(TRIM($G17),"-",""),".",""),"/",""),2))),DATEVALUE($G17))),"")) | V17: =IF($H17="","",IFERROR(IF(IF(ISNUMBER($H17),$H17,IFERROR(TIMEVALUE($H17),VALUE($H17)))>=100,INT(IF(ISNUMBER($H17),$H17,IFERROR(TIMEVALUE($H17),VALUE($H17)))/100)*60+MOD(IF(ISNUMBER($H17),$H17,IFERROR(TIMEVALUE($H17),VALUE($H17))),100),IF(IF(ISNUMBER($H17),$H17,IFERROR(TIMEVALUE($H17),VALUE($H17)))>=1,ROUND(IF(ISNUMBER($H17),$H17,IFERROR(TIMEVALUE($H17),VALUE($H17)))*60,0),ROUND(MOD(IF(ISNUMBER($H17),$H17,IFERROR(TIMEVALUE($H17),VALUE($H17))),1)*1440,0))),"")) | W17: =IF($I17="","",IFERROR(IF(IF(ISNUMBER($I17),$I17,IFERROR(TIMEVALUE($I17),VALUE($I17)))>=100,INT(IF(ISNUMBER($I17),$I17,IFERROR(TIMEVALUE($I17),VALUE($I17)))/100)*60+MOD(IF(ISNUMBER($I17),$I17,IFERROR(TIMEVALUE($I17),VALUE($I17))),100),IF(IF(ISNUMBER($I17),$I17,IFERROR(TIMEVALUE($I17),VALUE($I17)))>=1,ROUND(IF(ISNUMBER($I17),$I17,IFERROR(TIMEVALUE($I17),VALUE($I17)))*60,0),ROUND(MOD(IF(ISNUMBER($I17),$I17,IFERROR(TIMEVALUE($I17),VALUE($I17))),1)*1440,0))),"")) | X17: =IF($P17="","",IFERROR(IF(ISNUMBER($P17),IF($P17>19000000,DATE(INT($P17/10000),MOD(INT($P17/100),100),MOD($P17,100)),INT($P17)),IF(LEN(SUBSTITUTE(SUBSTITUTE(SUBSTITUTE(TRIM($P17),"-",""),".",""),"/",""))=8,DATE(VALUE(LEFT(SUBSTITUTE(SUBSTITUTE(SUBSTITUTE(TRIM($P17),"-",""),".",""),"/",""),4)),VALUE(MID(SUBSTITUTE(SUBSTITUTE(SUBSTITUTE(TRIM($P17),"-",""),".",""),"/",""),5,2)),VALUE(RIGHT(SUBSTITUTE(SUBSTITUTE(SUBSTITUTE(TRIM($P17),"-",""),".",""),"/",""),2))),DATEVALUE($P17))),"")) | Y17: =IF($M17="","",IFERROR(INDEX(강사DB!$D$4:$D$53,MATCH($M17,강사DB!$A$4:$A$53,0)),"")) | Z17: =IF($B17<>"결제완료","",IF(OR($Y17="",$J17=""),"",$Y17*$J17+MAX(0,N($K17)-1)*설정!$J$7)) | AA17: =IF(AND($D17<>"",$B17="결제완료"),N($N17),"") | AB17: =IF($D17="","",IF($F17<>"",$F17,$D17)&IF($B17="상담중"," (상담)","")) | AC17: =IF(AND($D17<>"",OR($B17="결제완료",$B17="상담중")),1,0) -> 0 | AD17: =IF(OR($Z17="",$U17=""),0,IFERROR(IF(COUNTIFS(INDEX(g_grid,0,2*MATCH($M17,강사DB!$A$4:$A$15,0)),"<>",g_s,"<="&$U17,g_e,">="&$U17)>0,1,0),0)) -> 0 | AF17: =IF(AND($D17<>"",$B17="결제완료",$T17="대여"),설정!$J$5,"") | AG17: =IF($D17="","",IF(AND($E17="",$R17=""),$AB17,"☎ "&IF($E17="","-",$E17)&IF($R17<>""," ※ "&$R17,"")&IF($B17="상담중"," (상담)",""))) | AH17: =IF(AND($D17<>"",$B17="결제완료",$O17="스마트스토어"),ROUND(N($N17)*설정!$J$6,0),"") | AI17: =IF($D17="","",ROW()) | AJ17: =IF(OR($AC17<>1,$M17=""),0,IF(ISNUMBER(SEARCH("퇴사",IFERROR(INDEX(강사DB!$G$4:$G$53,MATCH($M17,강사DB!$A$4:$A$53,0)),""))),1,0)) -> 0
... A1004: =IF($D1004="","",COUNTA($D$5:$D1004)) | J1004: =IF(OR($V1004="",$W1004=""),"",ROUND(($W1004-$V1004)/60,2)) | K1004: =IF($F1004="","",LEN($F1004)-LEN(SUBSTITUTE($F1004,",",""))+1) | L1004: =IF($K1004="","","1:"&$K1004) | S1004: =IF(OR($AC1004=0,$U1004="",$M1004="",$V1004="",$W1004=""),"",IF(COUNTIFS(m_teacher,$M1004,m_date,$U1004,m_active,1,m_start,"<"&$W1004,m_end,">"&$V1004)>1,"충돌","")) | U1004: =IF($G1004="","",IFERROR(IF(ISNUMBER($G1004),IF($G1004>19000000,DATE(INT($G1004/10000),MOD(INT($G1004/100),100),MOD($G1004,100)),INT($G1004)),IF(LEN(SUBSTITUTE(SUBSTITUTE(SUBSTITUTE(TRIM($G1004),"-",""),".",""),"/",""))=8,DATE(VALUE(LEFT(SUBSTITUTE(SUBSTITUTE(SUBSTITUTE(TRIM($G1004),"-",""),".",""),"/",""),4)),VALUE(MID(SUBSTITUTE(SUBSTITUTE(SUBSTITUTE(TRIM($G1004),"-",""),".",""),"/",""),5,2)),VALUE(RIGHT(SUBSTITUTE(SUBSTITUTE(SUBSTITUTE(TRIM($G1004),"-",""),".",""),"/",""),2))),DATEVALUE($G1004))),"")) | V1004: =IF($H1004="","",IFERROR(IF(IF(ISNUMBER($H1004),$H1004,IFERROR(TIMEVALUE($H1004),VALUE($H1004)))>=100,INT(IF(ISNUMBER($H1004),$H1004,IFERROR(TIMEVALUE($H1004),VALUE($H1004)))/100)*60+MOD(IF(ISNUMBER($H1004),$H1004,IFERROR(TIMEVALUE($H1004),VALUE($H1004))),100),IF(IF(ISNUMBER($H1004),$H1004,IFERROR(TIMEVALUE($H1004),VALUE($H1004)))>=1,ROUND(IF(ISNUMBER($H1004),$H1004,IFERROR(TIMEVALUE($H1004),VALUE($H1004)))*60,0),ROUND(MOD(IF(ISNUMBER($H1004),$H1004,IFERROR(TIMEVALUE($H1004),VALUE($H1004))),1)*1440,0))),"")) | W1004: =IF($I1004="","",IFERROR(IF(IF(ISNUMBER($I1004),$I1004,IFERROR(TIMEVALUE($I1004),VALUE($I1004)))>=100,INT(IF(ISNUMBER($I1004),$I1004,IFERROR(TIMEVALUE($I1004),VALUE($I1004)))/100)*60+MOD(IF(ISNUMBER($I1004),$I1004,IFERROR(TIMEVALUE($I1004),VALUE($I1004))),100),IF(IF(ISNUMBER($I1004),$I1004,IFERROR(TIMEVALUE($I1004),VALUE($I1004)))>=1,ROUND(IF(ISNUMBER($I1004),$I1004,IFERROR(TIMEVALUE($I1004),VALUE($I1004)))*60,0),ROUND(MOD(IF(ISNUMBER($I1004),$I1004,IFERROR(TIMEVALUE($I1004),VALUE($I1004))),1)*1440,0))),"")) | X1004: =IF($P1004="","",IFERROR(IF(ISNUMBER($P1004),IF($P1004>19000000,DATE(INT($P1004/10000),MOD(INT($P1004/100),100),MOD($P1004,100)),INT($P1004)),IF(LEN(SUBSTITUTE(SUBSTITUTE(SUBSTITUTE(TRIM($P1004),"-",""),".",""),"/",""))=8,DATE(VALUE(LEFT(SUBSTITUTE(SUBSTITUTE(SUBSTITUTE(TRIM($P1004),"-",""),".",""),"/",""),4)),VALUE(MID(SUBSTITUTE(SUBSTITUTE(SUBSTITUTE(TRIM($P1004),"-",""),".",""),"/",""),5,2)),VALUE(RIGHT(SUBSTITUTE(SUBSTITUTE(SUBSTITUTE(TRIM($P1004),"-",""),".",""),"/",""),2))),DATEVALUE($P1004))),"")) | Y1004: =IF($M1004="","",IFERROR(INDEX(강사DB!$D$4:$D$53,MATCH($M1004,강사DB!$A$4:$A$53,0)),"")) | Z1004: =IF($B1004<>"결제완료","",IF(OR($Y1004="",$J1004=""),"",$Y1004*$J1004+MAX(0,N($K1004)-1)*설정!$J$7)) | AA1004: =IF(AND($D1004<>"",$B1004="결제완료"),N($N1004),"") | AB1004: =IF($D1004="","",IF($F1004<>"",$F1004,$D1004)&IF($B1004="상담중"," (상담)","")) | AC1004: =IF(AND($D1004<>"",OR($B1004="결제완료",$B1004="상담중")),1,0) -> 0 | AD1004: =IF(OR($Z1004="",$U1004=""),0,IFERROR(IF(COUNTIFS(INDEX(g_grid,0,2*MATCH($M1004,강사DB!$A$4:$A$15,0)),"<>",g_s,"<="&$U1004,g_e,">="&$U1004)>0,1,0),0)) -> 0 | AF1004: =IF(AND($D1004<>"",$B1004="결제완료",$T1004="대여"),설정!$J$5,"") | AG1004: =IF($D1004="","",IF(AND($E1004="",$R1004=""),$AB1004,"☎ "&IF($E1004="","-",$E1004)&IF($R1004<>""," ※ "&$R1004,"")&IF($B1004="상담중"," (상담)",""))) | AH1004: =IF(AND($D1004<>"",$B1004="결제완료",$O1004="스마트스토어"),ROUND(N($N1004)*설정!$J$6,0),"") | AI1004: =IF($D1004="","",ROW()) | AJ1004: =IF(OR($AC1004<>1,$M1004=""),0,IF(ISNUMBER(SEARCH("퇴사",IFERROR(INDEX(강사DB!$G$4:$G$53,MATCH($M1004,강사DB!$A$4:$A$53,0)),""))),1,0)) -> 0

Sheet 강습표_2026년12월
A1: 2026년 12월 강습표
A2: 기준월 | C2: 46357 | E2: 첫 주 월요일 | G2: =$C$2-WEEKDAY($C$2,2)+1 -> 46356 | I2: MASTER의 결제완료·상담중 강습이 자동 표시: 칸에는 강습생(나이)만 표시 · 연락처·시간·특이사항은 칸 메모(마우스 올리기/클릭)로 확인 (구글 시트 자동 스크립트 설치 시). 취소로 바꾸면 사라집니다. 노랑 = 상담중 · 초록 = 결제완료 · 빨강 '충돌' = 같은 강사 같은 시간 2건 이상 · 9시 칸에는 9시 이전 시작 강습도 표시.
A3: ="1주차 "&TEXT($G$2+0,"m/d")&" ~ "&TEXT($G$2+6,"m/d") -> 1주차 11/30 ~ 12/6 | O3: ="2주차 "&TEXT($G$2+7,"m/d")&" ~ "&TEXT($G$2+13,"m/d") -> 2주차 12/7 ~ 12/13 | AC3: ="3주차 "&TEXT($G$2+14,"m/d")&" ~ "&TEXT($G$2+20,"m/d") -> 3주차 12/14 ~ 12/20 | AQ3: ="4주차 "&TEXT($G$2+21,"m/d")&" ~ "&TEXT($G$2+27,"m/d") -> 4주차 12/21 ~ 12/27 | BE3: ="5주차 "&TEXT($G$2+28,"m/d")&" ~ "&TEXT($G$2+34,"m/d") -> 5주차 12/28 ~ 1/3
A4: 요일/날짜 | B4: 시간 | C4: =IF(설정!$N$4="","",설정!$N$4) -> 김건진 | D4: =IF(설정!$N$5="","",설정!$N$5) -> 김준태 | E4: =IF(설정!$N$6="","",설정!$N$6) -> 이민규 | F4: =IF(설정!$N$7="","",설정!$N$7) -> 송지성 | G4: =IF(설정!$N$8="","",설정!$N$8) -> 박세근 | H4: =IF(설정!$N$9="","",설정!$N$9) -> 프리랜서A | I4: =IF(설정!$N$10="","",설정!$N$10) -> 프리랜서B | J4: =IF(설정!$N$11="","",설정!$N$11) | K4: =IF(설정!$N$12="","",설정!$N$12) | L4: =IF(설정!$N$13="","",설정!$N$13) | M4: =IF(설정!$N$14="","",설정!$N$14) | N4: =IF(설정!$N$15="","",설정!$N$15) | O4: 요일/날짜 | P4: 시간 | Q4: =IF(설정!$N$4="","",설정!$N$4) -> 김건진 | R4: =IF(설정!$N$5="","",설정!$N$5) -> 김준태 | S4: =IF(설정!$N$6="","",설정!$N$6) -> 이민규 | T4: =IF(설정!$N$7="","",설정!$N$7) -> 송지성 | U4: =IF(설정!$N$8="","",설정!$N$8) -> 박세근 | V4: =IF(설정!$N$9="","",설정!$N$9) -> 프리랜서A | W4: =IF(설정!$N$10="","",설정!$N$10) -> 프리랜서B | X4: =IF(설정!$N$11="","",설정!$N$11) | Y4: =IF(설정!$N$12="","",설정!$N$12) | Z4: =IF(설정!$N$13="","",설정!$N$13) | AA4: =IF(설정!$N$14="","",설정!$N$14) | AB4: =IF(설정!$N$15="","",설정!$N$15) | AC4: 요일/날짜 | AD4: 시간 | AE4: =IF(설정!$N$4="","",설정!$N$4) -> 김건진 | AF4: =IF(설정!$N$5="","",설정!$N$5) -> 김준태 | AG4: =IF(설정!$N$6="","",설정!$N$6) -> 이민규 | AH4: =IF(설정!$N$7="","",설정!$N$7) -> 송지성 | AI4: =IF(설정!$N$8="","",설정!$N$8) -> 박세근 | AJ4: =IF(설정!$N$9="","",설정!$N$9) -> 프리랜서A | AK4: =IF(설정!$N$10="","",설정!$N$10) -> 프리랜서B | AL4: =IF(설정!$N$11="","",설정!$N$11) | AM4: =IF(설정!$N$12="","",설정!$N$12) | AN4: =IF(설정!$N$13="","",설정!$N$13) | AO4: =IF(설정!$N$14="","",설정!$N$14) | AP4: =IF(설정!$N$15="","",설정!$N$15) | AQ4: 요일/날짜 | AR4: 시간 | AS4: =IF(설정!$N$4="","",설정!$N$4) -> 김건진 | AT4: =IF(설정!$N$5="","",설정!$N$5) -> 김준태 | AU4: =IF(설정!$N$6="","",설정!$N$6) -> 이민규 | AV4: =IF(설정!$N$7="","",설정!$N$7) -> 송지성 | AW4: =IF(설정!$N$8="","",설정!$N$8) -> 박세근 | AX4: =IF(설정!$N$9="","",설정!$N$9) -> 프리랜서A | AY4: =IF(설정!$N$10="","",설정!$N$10) -> 프리랜서B | AZ4: =IF(설정!$N$11="","",설정!$N$11) | BA4: =IF(설정!$N$12="","",설정!$N$12) | BB4: =IF(설정!$N$13="","",설정!$N$13) | BC4: =IF(설정!$N$14="","",설정!$N$14) | BD4: =IF(설정!$N$15="","",설정!$N$15) | BE4: 요일/날짜 | BF4: 시간 | BG4: =IF(설정!$N$4="","",설정!$N$4) -> 김건진 | BH4: =IF(설정!$N$5="","",설정!$N$5) -> 김준태 | BI4: =IF(설정!$N$6="","",설정!$N$6) -> 이민규 | BJ4: =IF(설정!$N$7="","",설정!$N$7) -> 송지성 | BK4: =IF(설정!$N$8="","",설정!$N$8) -> 박세근 | BL4: =IF(설정!$N$9="","",설정!$N$9) -> 프리랜서A | BM4: =IF(설정!$N$10="","",설정!$N$10) -> 프리랜서B | BN4: =IF(설정!$N$11="","",설정!$N$11) | BO4: =IF(설정!$N$12="","",설정!$N$12) | BP4: =IF(설정!$N$13="","",설정!$N$13) | BQ4: =IF(설정!$N$14="","",설정!$N$14) | BR4: =IF(설정!$N$15="","",설정!$N$15)
